[2024-12-24T22:26:32.181+0000] {processor.py:186} INFO - Started process (PID=65) to work on /opt/airflow/dags/dynamic_dags.py
[2024-12-24T22:26:32.185+0000] {processor.py:914} INFO - Processing file /opt/airflow/dags/dynamic_dags.py for tasks to queue
[2024-12-24T22:26:32.189+0000] {logging_mixin.py:190} INFO - [2024-12-24T22:26:32.189+0000] {dagbag.py:588} INFO - Filling up the DagBag from /opt/airflow/dags/dynamic_dags.py
[2024-12-24T22:26:40.403+0000] {logging_mixin.py:190} INFO - [2024-12-24T22:26:40.374+0000] {dagbag.py:387} ERROR - Failed to import: /opt/airflow/dags/dynamic_dags.py
Traceback (most recent call last):
  File "/home/airflow/.local/lib/python3.12/site-packages/urllib3/connection.py", line 199, in _new_conn
    sock = connection.create_connection(
           ^^^^^^^^^^^^^^^^^^^^^^^^^^^^^
  File "/home/airflow/.local/lib/python3.12/site-packages/urllib3/util/connection.py", line 60, in create_connection
    for res in socket.getaddrinfo(host, port, family, socket.SOCK_STREAM):
               ^^^^^^^^^^^^^^^^^^^^^^^^^^^^^^^^^^^^^^^^^^^^^^^^^^^^^^^^^^
  File "/usr/local/lib/python3.12/socket.py", line 976, in getaddrinfo
    for res in _socket.getaddrinfo(host, port, family, type, proto, flags):
               ^^^^^^^^^^^^^^^^^^^^^^^^^^^^^^^^^^^^^^^^^^^^^^^^^^^^^^^^^^^
socket.gaierror: [Errno -2] Name or service not known

The above exception was the direct cause of the following exception:

Traceback (most recent call last):
  File "/home/airflow/.local/lib/python3.12/site-packages/urllib3/connectionpool.py", line 789, in urlopen
    response = self._make_request(
               ^^^^^^^^^^^^^^^^^^^
  File "/home/airflow/.local/lib/python3.12/site-packages/urllib3/connectionpool.py", line 495, in _make_request
    conn.request(
  File "/home/airflow/.local/lib/python3.12/site-packages/urllib3/connection.py", line 441, in request
    self.endheaders()
  File "/usr/local/lib/python3.12/http/client.py", line 1331, in endheaders
    self._send_output(message_body, encode_chunked=encode_chunked)
  File "/usr/local/lib/python3.12/http/client.py", line 1091, in _send_output
    self.send(msg)
  File "/usr/local/lib/python3.12/http/client.py", line 1035, in send
    self.connect()
  File "/home/airflow/.local/lib/python3.12/site-packages/urllib3/connection.py", line 279, in connect
    self.sock = self._new_conn()
                ^^^^^^^^^^^^^^^^
  File "/home/airflow/.local/lib/python3.12/site-packages/urllib3/connection.py", line 206, in _new_conn
    raise NameResolutionError(self.host, self, e) from e
urllib3.exceptions.NameResolutionError: <urllib3.connection.HTTPConnection object at 0x7f9e45d456d0>: Failed to resolve 'host.docker.internal' ([Errno -2] Name or service not known)

The above exception was the direct cause of the following exception:

Traceback (most recent call last):
  File "/home/airflow/.local/lib/python3.12/site-packages/requests/adapters.py", line 667, in send
    resp = conn.urlopen(
           ^^^^^^^^^^^^^
  File "/home/airflow/.local/lib/python3.12/site-packages/urllib3/connectionpool.py", line 843, in urlopen
    retries = retries.increment(
              ^^^^^^^^^^^^^^^^^^
  File "/home/airflow/.local/lib/python3.12/site-packages/urllib3/util/retry.py", line 519, in increment
    raise MaxRetryError(_pool, url, reason) from reason  # type: ignore[arg-type]
    ^^^^^^^^^^^^^^^^^^^^^^^^^^^^^^^^^^^^^^^^^^^^^^^^^^^
urllib3.exceptions.MaxRetryError: HTTPConnectionPool(host='host.docker.internal', port=8000): Max retries exceeded with url: /api/simulators/ (Caused by NameResolutionError("<urllib3.connection.HTTPConnection object at 0x7f9e45d456d0>: Failed to resolve 'host.docker.internal' ([Errno -2] Name or service not known)"))

During handling of the above exception, another exception occurred:

Traceback (most recent call last):
  File "/home/airflow/.local/lib/python3.12/site-packages/airflow/models/dagbag.py", line 383, in parse
    loader.exec_module(new_module)
  File "<frozen importlib._bootstrap_external>", line 999, in exec_module
  File "<frozen importlib._bootstrap>", line 488, in _call_with_frames_removed
  File "/opt/airflow/dags/dynamic_dags.py", line 22, in <module>
    simulators = fetch_simulator_instances()
                 ^^^^^^^^^^^^^^^^^^^^^^^^^^^
  File "/opt/airflow/dags/dynamic_dags.py", line 10, in fetch_simulator_instances
    response = requests.get('http://host.docker.internal:8000/api/simulators/')
               ^^^^^^^^^^^^^^^^^^^^^^^^^^^^^^^^^^^^^^^^^^^^^^^^^^^^^^^^^^^^^^^^
  File "/home/airflow/.local/lib/python3.12/site-packages/requests/api.py", line 73, in get
    return request("get", url, params=params, **kwargs)
           ^^^^^^^^^^^^^^^^^^^^^^^^^^^^^^^^^^^^^^^^^^^^
  File "/home/airflow/.local/lib/python3.12/site-packages/requests/api.py", line 59, in request
    return session.request(method=method, url=url, **kwargs)
           ^^^^^^^^^^^^^^^^^^^^^^^^^^^^^^^^^^^^^^^^^^^^^^^^^
  File "/home/airflow/.local/lib/python3.12/site-packages/requests/sessions.py", line 589, in request
    resp = self.send(prep, **send_kwargs)
           ^^^^^^^^^^^^^^^^^^^^^^^^^^^^^^
  File "/home/airflow/.local/lib/python3.12/site-packages/requests/sessions.py", line 703, in send
    r = adapter.send(request, **kwargs)
        ^^^^^^^^^^^^^^^^^^^^^^^^^^^^^^^
  File "/home/airflow/.local/lib/python3.12/site-packages/requests/adapters.py", line 700, in send
    raise ConnectionError(e, request=request)
requests.exceptions.ConnectionError: HTTPConnectionPool(host='host.docker.internal', port=8000): Max retries exceeded with url: /api/simulators/ (Caused by NameResolutionError("<urllib3.connection.HTTPConnection object at 0x7f9e45d456d0>: Failed to resolve 'host.docker.internal' ([Errno -2] Name or service not known)"))
[2024-12-24T22:26:40.406+0000] {processor.py:927} WARNING - No viable dags retrieved from /opt/airflow/dags/dynamic_dags.py
[2024-12-24T22:26:40.431+0000] {processor.py:208} INFO - Processing /opt/airflow/dags/dynamic_dags.py took 8.259 seconds
[2024-12-24T22:27:11.397+0000] {processor.py:186} INFO - Started process (PID=162) to work on /opt/airflow/dags/dynamic_dags.py
[2024-12-24T22:27:11.398+0000] {processor.py:914} INFO - Processing file /opt/airflow/dags/dynamic_dags.py for tasks to queue
[2024-12-24T22:27:11.401+0000] {logging_mixin.py:190} INFO - [2024-12-24T22:27:11.400+0000] {dagbag.py:588} INFO - Filling up the DagBag from /opt/airflow/dags/dynamic_dags.py
[2024-12-24T22:27:19.502+0000] {logging_mixin.py:190} INFO - [2024-12-24T22:27:19.493+0000] {dagbag.py:387} ERROR - Failed to import: /opt/airflow/dags/dynamic_dags.py
Traceback (most recent call last):
  File "/home/airflow/.local/lib/python3.12/site-packages/urllib3/connection.py", line 199, in _new_conn
    sock = connection.create_connection(
           ^^^^^^^^^^^^^^^^^^^^^^^^^^^^^
  File "/home/airflow/.local/lib/python3.12/site-packages/urllib3/util/connection.py", line 60, in create_connection
    for res in socket.getaddrinfo(host, port, family, socket.SOCK_STREAM):
               ^^^^^^^^^^^^^^^^^^^^^^^^^^^^^^^^^^^^^^^^^^^^^^^^^^^^^^^^^^
  File "/usr/local/lib/python3.12/socket.py", line 976, in getaddrinfo
    for res in _socket.getaddrinfo(host, port, family, type, proto, flags):
               ^^^^^^^^^^^^^^^^^^^^^^^^^^^^^^^^^^^^^^^^^^^^^^^^^^^^^^^^^^^
socket.gaierror: [Errno -2] Name or service not known

The above exception was the direct cause of the following exception:

Traceback (most recent call last):
  File "/home/airflow/.local/lib/python3.12/site-packages/urllib3/connectionpool.py", line 789, in urlopen
    response = self._make_request(
               ^^^^^^^^^^^^^^^^^^^
  File "/home/airflow/.local/lib/python3.12/site-packages/urllib3/connectionpool.py", line 495, in _make_request
    conn.request(
  File "/home/airflow/.local/lib/python3.12/site-packages/urllib3/connection.py", line 441, in request
    self.endheaders()
  File "/usr/local/lib/python3.12/http/client.py", line 1331, in endheaders
    self._send_output(message_body, encode_chunked=encode_chunked)
  File "/usr/local/lib/python3.12/http/client.py", line 1091, in _send_output
    self.send(msg)
  File "/usr/local/lib/python3.12/http/client.py", line 1035, in send
    self.connect()
  File "/home/airflow/.local/lib/python3.12/site-packages/urllib3/connection.py", line 279, in connect
    self.sock = self._new_conn()
                ^^^^^^^^^^^^^^^^
  File "/home/airflow/.local/lib/python3.12/site-packages/urllib3/connection.py", line 206, in _new_conn
    raise NameResolutionError(self.host, self, e) from e
urllib3.exceptions.NameResolutionError: <urllib3.connection.HTTPConnection object at 0x7f9e45c676b0>: Failed to resolve 'host.docker.internal' ([Errno -2] Name or service not known)

The above exception was the direct cause of the following exception:

Traceback (most recent call last):
  File "/home/airflow/.local/lib/python3.12/site-packages/requests/adapters.py", line 667, in send
    resp = conn.urlopen(
           ^^^^^^^^^^^^^
  File "/home/airflow/.local/lib/python3.12/site-packages/urllib3/connectionpool.py", line 843, in urlopen
    retries = retries.increment(
              ^^^^^^^^^^^^^^^^^^
  File "/home/airflow/.local/lib/python3.12/site-packages/urllib3/util/retry.py", line 519, in increment
    raise MaxRetryError(_pool, url, reason) from reason  # type: ignore[arg-type]
    ^^^^^^^^^^^^^^^^^^^^^^^^^^^^^^^^^^^^^^^^^^^^^^^^^^^
urllib3.exceptions.MaxRetryError: HTTPConnectionPool(host='host.docker.internal', port=8000): Max retries exceeded with url: /api/simulators/ (Caused by NameResolutionError("<urllib3.connection.HTTPConnection object at 0x7f9e45c676b0>: Failed to resolve 'host.docker.internal' ([Errno -2] Name or service not known)"))

During handling of the above exception, another exception occurred:

Traceback (most recent call last):
  File "/home/airflow/.local/lib/python3.12/site-packages/airflow/models/dagbag.py", line 383, in parse
    loader.exec_module(new_module)
  File "<frozen importlib._bootstrap_external>", line 999, in exec_module
  File "<frozen importlib._bootstrap>", line 488, in _call_with_frames_removed
  File "/opt/airflow/dags/dynamic_dags.py", line 22, in <module>
    simulators = fetch_simulator_instances()
                 ^^^^^^^^^^^^^^^^^^^^^^^^^^^
  File "/opt/airflow/dags/dynamic_dags.py", line 10, in fetch_simulator_instances
    response = requests.get('http://host.docker.internal:8000/api/simulators/')
               ^^^^^^^^^^^^^^^^^^^^^^^^^^^^^^^^^^^^^^^^^^^^^^^^^^^^^^^^^^^^^^^^
  File "/home/airflow/.local/lib/python3.12/site-packages/requests/api.py", line 73, in get
    return request("get", url, params=params, **kwargs)
           ^^^^^^^^^^^^^^^^^^^^^^^^^^^^^^^^^^^^^^^^^^^^
  File "/home/airflow/.local/lib/python3.12/site-packages/requests/api.py", line 59, in request
    return session.request(method=method, url=url, **kwargs)
           ^^^^^^^^^^^^^^^^^^^^^^^^^^^^^^^^^^^^^^^^^^^^^^^^^
  File "/home/airflow/.local/lib/python3.12/site-packages/requests/sessions.py", line 589, in request
    resp = self.send(prep, **send_kwargs)
           ^^^^^^^^^^^^^^^^^^^^^^^^^^^^^^
  File "/home/airflow/.local/lib/python3.12/site-packages/requests/sessions.py", line 703, in send
    r = adapter.send(request, **kwargs)
        ^^^^^^^^^^^^^^^^^^^^^^^^^^^^^^^
  File "/home/airflow/.local/lib/python3.12/site-packages/requests/adapters.py", line 700, in send
    raise ConnectionError(e, request=request)
requests.exceptions.ConnectionError: HTTPConnectionPool(host='host.docker.internal', port=8000): Max retries exceeded with url: /api/simulators/ (Caused by NameResolutionError("<urllib3.connection.HTTPConnection object at 0x7f9e45c676b0>: Failed to resolve 'host.docker.internal' ([Errno -2] Name or service not known)"))
[2024-12-24T22:27:19.504+0000] {processor.py:927} WARNING - No viable dags retrieved from /opt/airflow/dags/dynamic_dags.py
[2024-12-24T22:27:19.520+0000] {processor.py:208} INFO - Processing /opt/airflow/dags/dynamic_dags.py took 8.127 seconds
[2024-12-24T22:27:49.648+0000] {processor.py:186} INFO - Started process (PID=256) to work on /opt/airflow/dags/dynamic_dags.py
[2024-12-24T22:27:49.650+0000] {processor.py:914} INFO - Processing file /opt/airflow/dags/dynamic_dags.py for tasks to queue
[2024-12-24T22:27:49.653+0000] {logging_mixin.py:190} INFO - [2024-12-24T22:27:49.652+0000] {dagbag.py:588} INFO - Filling up the DagBag from /opt/airflow/dags/dynamic_dags.py
[2024-12-24T22:27:57.773+0000] {logging_mixin.py:190} INFO - [2024-12-24T22:27:57.758+0000] {dagbag.py:387} ERROR - Failed to import: /opt/airflow/dags/dynamic_dags.py
Traceback (most recent call last):
  File "/home/airflow/.local/lib/python3.12/site-packages/urllib3/connection.py", line 199, in _new_conn
    sock = connection.create_connection(
           ^^^^^^^^^^^^^^^^^^^^^^^^^^^^^
  File "/home/airflow/.local/lib/python3.12/site-packages/urllib3/util/connection.py", line 60, in create_connection
    for res in socket.getaddrinfo(host, port, family, socket.SOCK_STREAM):
               ^^^^^^^^^^^^^^^^^^^^^^^^^^^^^^^^^^^^^^^^^^^^^^^^^^^^^^^^^^
  File "/usr/local/lib/python3.12/socket.py", line 976, in getaddrinfo
    for res in _socket.getaddrinfo(host, port, family, type, proto, flags):
               ^^^^^^^^^^^^^^^^^^^^^^^^^^^^^^^^^^^^^^^^^^^^^^^^^^^^^^^^^^^
socket.gaierror: [Errno -2] Name or service not known

The above exception was the direct cause of the following exception:

Traceback (most recent call last):
  File "/home/airflow/.local/lib/python3.12/site-packages/urllib3/connectionpool.py", line 789, in urlopen
    response = self._make_request(
               ^^^^^^^^^^^^^^^^^^^
  File "/home/airflow/.local/lib/python3.12/site-packages/urllib3/connectionpool.py", line 495, in _make_request
    conn.request(
  File "/home/airflow/.local/lib/python3.12/site-packages/urllib3/connection.py", line 441, in request
    self.endheaders()
  File "/usr/local/lib/python3.12/http/client.py", line 1331, in endheaders
    self._send_output(message_body, encode_chunked=encode_chunked)
  File "/usr/local/lib/python3.12/http/client.py", line 1091, in _send_output
    self.send(msg)
  File "/usr/local/lib/python3.12/http/client.py", line 1035, in send
    self.connect()
  File "/home/airflow/.local/lib/python3.12/site-packages/urllib3/connection.py", line 279, in connect
    self.sock = self._new_conn()
                ^^^^^^^^^^^^^^^^
  File "/home/airflow/.local/lib/python3.12/site-packages/urllib3/connection.py", line 206, in _new_conn
    raise NameResolutionError(self.host, self, e) from e
urllib3.exceptions.NameResolutionError: <urllib3.connection.HTTPConnection object at 0x7f9e45c66bd0>: Failed to resolve 'host.docker.internal' ([Errno -2] Name or service not known)

The above exception was the direct cause of the following exception:

Traceback (most recent call last):
  File "/home/airflow/.local/lib/python3.12/site-packages/requests/adapters.py", line 667, in send
    resp = conn.urlopen(
           ^^^^^^^^^^^^^
  File "/home/airflow/.local/lib/python3.12/site-packages/urllib3/connectionpool.py", line 843, in urlopen
    retries = retries.increment(
              ^^^^^^^^^^^^^^^^^^
  File "/home/airflow/.local/lib/python3.12/site-packages/urllib3/util/retry.py", line 519, in increment
    raise MaxRetryError(_pool, url, reason) from reason  # type: ignore[arg-type]
    ^^^^^^^^^^^^^^^^^^^^^^^^^^^^^^^^^^^^^^^^^^^^^^^^^^^
urllib3.exceptions.MaxRetryError: HTTPConnectionPool(host='host.docker.internal', port=8000): Max retries exceeded with url: /api/simulators/ (Caused by NameResolutionError("<urllib3.connection.HTTPConnection object at 0x7f9e45c66bd0>: Failed to resolve 'host.docker.internal' ([Errno -2] Name or service not known)"))

During handling of the above exception, another exception occurred:

Traceback (most recent call last):
  File "/home/airflow/.local/lib/python3.12/site-packages/airflow/models/dagbag.py", line 383, in parse
    loader.exec_module(new_module)
  File "<frozen importlib._bootstrap_external>", line 999, in exec_module
  File "<frozen importlib._bootstrap>", line 488, in _call_with_frames_removed
  File "/opt/airflow/dags/dynamic_dags.py", line 22, in <module>
    simulators = fetch_simulator_instances()
                 ^^^^^^^^^^^^^^^^^^^^^^^^^^^
  File "/opt/airflow/dags/dynamic_dags.py", line 10, in fetch_simulator_instances
    response = requests.get('http://host.docker.internal:8000/api/simulators/')
               ^^^^^^^^^^^^^^^^^^^^^^^^^^^^^^^^^^^^^^^^^^^^^^^^^^^^^^^^^^^^^^^^
  File "/home/airflow/.local/lib/python3.12/site-packages/requests/api.py", line 73, in get
    return request("get", url, params=params, **kwargs)
           ^^^^^^^^^^^^^^^^^^^^^^^^^^^^^^^^^^^^^^^^^^^^
  File "/home/airflow/.local/lib/python3.12/site-packages/requests/api.py", line 59, in request
    return session.request(method=method, url=url, **kwargs)
           ^^^^^^^^^^^^^^^^^^^^^^^^^^^^^^^^^^^^^^^^^^^^^^^^^
  File "/home/airflow/.local/lib/python3.12/site-packages/requests/sessions.py", line 589, in request
    resp = self.send(prep, **send_kwargs)
           ^^^^^^^^^^^^^^^^^^^^^^^^^^^^^^
  File "/home/airflow/.local/lib/python3.12/site-packages/requests/sessions.py", line 703, in send
    r = adapter.send(request, **kwargs)
        ^^^^^^^^^^^^^^^^^^^^^^^^^^^^^^^
  File "/home/airflow/.local/lib/python3.12/site-packages/requests/adapters.py", line 700, in send
    raise ConnectionError(e, request=request)
requests.exceptions.ConnectionError: HTTPConnectionPool(host='host.docker.internal', port=8000): Max retries exceeded with url: /api/simulators/ (Caused by NameResolutionError("<urllib3.connection.HTTPConnection object at 0x7f9e45c66bd0>: Failed to resolve 'host.docker.internal' ([Errno -2] Name or service not known)"))
[2024-12-24T22:27:57.775+0000] {processor.py:927} WARNING - No viable dags retrieved from /opt/airflow/dags/dynamic_dags.py
[2024-12-24T22:27:57.804+0000] {processor.py:208} INFO - Processing /opt/airflow/dags/dynamic_dags.py took 8.160 seconds
[2024-12-24T22:28:28.101+0000] {processor.py:186} INFO - Started process (PID=320) to work on /opt/airflow/dags/dynamic_dags.py
[2024-12-24T22:28:28.103+0000] {processor.py:914} INFO - Processing file /opt/airflow/dags/dynamic_dags.py for tasks to queue
[2024-12-24T22:28:28.106+0000] {logging_mixin.py:190} INFO - [2024-12-24T22:28:28.106+0000] {dagbag.py:588} INFO - Filling up the DagBag from /opt/airflow/dags/dynamic_dags.py
[2024-12-24T22:28:36.234+0000] {logging_mixin.py:190} INFO - [2024-12-24T22:28:36.220+0000] {dagbag.py:387} ERROR - Failed to import: /opt/airflow/dags/dynamic_dags.py
Traceback (most recent call last):
  File "/home/airflow/.local/lib/python3.12/site-packages/urllib3/connection.py", line 199, in _new_conn
    sock = connection.create_connection(
           ^^^^^^^^^^^^^^^^^^^^^^^^^^^^^
  File "/home/airflow/.local/lib/python3.12/site-packages/urllib3/util/connection.py", line 60, in create_connection
    for res in socket.getaddrinfo(host, port, family, socket.SOCK_STREAM):
               ^^^^^^^^^^^^^^^^^^^^^^^^^^^^^^^^^^^^^^^^^^^^^^^^^^^^^^^^^^
  File "/usr/local/lib/python3.12/socket.py", line 976, in getaddrinfo
    for res in _socket.getaddrinfo(host, port, family, type, proto, flags):
               ^^^^^^^^^^^^^^^^^^^^^^^^^^^^^^^^^^^^^^^^^^^^^^^^^^^^^^^^^^^
socket.gaierror: [Errno -2] Name or service not known

The above exception was the direct cause of the following exception:

Traceback (most recent call last):
  File "/home/airflow/.local/lib/python3.12/site-packages/urllib3/connectionpool.py", line 789, in urlopen
    response = self._make_request(
               ^^^^^^^^^^^^^^^^^^^
  File "/home/airflow/.local/lib/python3.12/site-packages/urllib3/connectionpool.py", line 495, in _make_request
    conn.request(
  File "/home/airflow/.local/lib/python3.12/site-packages/urllib3/connection.py", line 441, in request
    self.endheaders()
  File "/usr/local/lib/python3.12/http/client.py", line 1331, in endheaders
    self._send_output(message_body, encode_chunked=encode_chunked)
  File "/usr/local/lib/python3.12/http/client.py", line 1091, in _send_output
    self.send(msg)
  File "/usr/local/lib/python3.12/http/client.py", line 1035, in send
    self.connect()
  File "/home/airflow/.local/lib/python3.12/site-packages/urllib3/connection.py", line 279, in connect
    self.sock = self._new_conn()
                ^^^^^^^^^^^^^^^^
  File "/home/airflow/.local/lib/python3.12/site-packages/urllib3/connection.py", line 206, in _new_conn
    raise NameResolutionError(self.host, self, e) from e
urllib3.exceptions.NameResolutionError: <urllib3.connection.HTTPConnection object at 0x7f9e0a4a7020>: Failed to resolve 'host.docker.internal' ([Errno -2] Name or service not known)

The above exception was the direct cause of the following exception:

Traceback (most recent call last):
  File "/home/airflow/.local/lib/python3.12/site-packages/requests/adapters.py", line 667, in send
    resp = conn.urlopen(
           ^^^^^^^^^^^^^
  File "/home/airflow/.local/lib/python3.12/site-packages/urllib3/connectionpool.py", line 843, in urlopen
    retries = retries.increment(
              ^^^^^^^^^^^^^^^^^^
  File "/home/airflow/.local/lib/python3.12/site-packages/urllib3/util/retry.py", line 519, in increment
    raise MaxRetryError(_pool, url, reason) from reason  # type: ignore[arg-type]
    ^^^^^^^^^^^^^^^^^^^^^^^^^^^^^^^^^^^^^^^^^^^^^^^^^^^
urllib3.exceptions.MaxRetryError: HTTPConnectionPool(host='host.docker.internal', port=8000): Max retries exceeded with url: /api/simulators/ (Caused by NameResolutionError("<urllib3.connection.HTTPConnection object at 0x7f9e0a4a7020>: Failed to resolve 'host.docker.internal' ([Errno -2] Name or service not known)"))

During handling of the above exception, another exception occurred:

Traceback (most recent call last):
  File "/home/airflow/.local/lib/python3.12/site-packages/airflow/models/dagbag.py", line 383, in parse
    loader.exec_module(new_module)
  File "<frozen importlib._bootstrap_external>", line 999, in exec_module
  File "<frozen importlib._bootstrap>", line 488, in _call_with_frames_removed
  File "/opt/airflow/dags/dynamic_dags.py", line 22, in <module>
    simulators = fetch_simulator_instances()
                 ^^^^^^^^^^^^^^^^^^^^^^^^^^^
  File "/opt/airflow/dags/dynamic_dags.py", line 10, in fetch_simulator_instances
    response = requests.get('http://host.docker.internal:8000/api/simulators/')
               ^^^^^^^^^^^^^^^^^^^^^^^^^^^^^^^^^^^^^^^^^^^^^^^^^^^^^^^^^^^^^^^^
  File "/home/airflow/.local/lib/python3.12/site-packages/requests/api.py", line 73, in get
    return request("get", url, params=params, **kwargs)
           ^^^^^^^^^^^^^^^^^^^^^^^^^^^^^^^^^^^^^^^^^^^^
  File "/home/airflow/.local/lib/python3.12/site-packages/requests/api.py", line 59, in request
    return session.request(method=method, url=url, **kwargs)
           ^^^^^^^^^^^^^^^^^^^^^^^^^^^^^^^^^^^^^^^^^^^^^^^^^
  File "/home/airflow/.local/lib/python3.12/site-packages/requests/sessions.py", line 589, in request
    resp = self.send(prep, **send_kwargs)
           ^^^^^^^^^^^^^^^^^^^^^^^^^^^^^^
  File "/home/airflow/.local/lib/python3.12/site-packages/requests/sessions.py", line 703, in send
    r = adapter.send(request, **kwargs)
        ^^^^^^^^^^^^^^^^^^^^^^^^^^^^^^^
  File "/home/airflow/.local/lib/python3.12/site-packages/requests/adapters.py", line 700, in send
    raise ConnectionError(e, request=request)
requests.exceptions.ConnectionError: HTTPConnectionPool(host='host.docker.internal', port=8000): Max retries exceeded with url: /api/simulators/ (Caused by NameResolutionError("<urllib3.connection.HTTPConnection object at 0x7f9e0a4a7020>: Failed to resolve 'host.docker.internal' ([Errno -2] Name or service not known)"))
[2024-12-24T22:28:36.236+0000] {processor.py:927} WARNING - No viable dags retrieved from /opt/airflow/dags/dynamic_dags.py
[2024-12-24T22:28:36.251+0000] {processor.py:208} INFO - Processing /opt/airflow/dags/dynamic_dags.py took 8.154 seconds
[2024-12-24T22:29:06.596+0000] {processor.py:186} INFO - Started process (PID=386) to work on /opt/airflow/dags/dynamic_dags.py
[2024-12-24T22:29:06.599+0000] {processor.py:914} INFO - Processing file /opt/airflow/dags/dynamic_dags.py for tasks to queue
[2024-12-24T22:29:06.601+0000] {logging_mixin.py:190} INFO - [2024-12-24T22:29:06.601+0000] {dagbag.py:588} INFO - Filling up the DagBag from /opt/airflow/dags/dynamic_dags.py
[2024-12-24T22:29:16.964+0000] {logging_mixin.py:190} INFO - [2024-12-24T22:29:16.951+0000] {dagbag.py:387} ERROR - Failed to import: /opt/airflow/dags/dynamic_dags.py
Traceback (most recent call last):
  File "/home/airflow/.local/lib/python3.12/site-packages/urllib3/connection.py", line 199, in _new_conn
    sock = connection.create_connection(
           ^^^^^^^^^^^^^^^^^^^^^^^^^^^^^
  File "/home/airflow/.local/lib/python3.12/site-packages/urllib3/util/connection.py", line 60, in create_connection
    for res in socket.getaddrinfo(host, port, family, socket.SOCK_STREAM):
               ^^^^^^^^^^^^^^^^^^^^^^^^^^^^^^^^^^^^^^^^^^^^^^^^^^^^^^^^^^
  File "/usr/local/lib/python3.12/socket.py", line 976, in getaddrinfo
    for res in _socket.getaddrinfo(host, port, family, type, proto, flags):
               ^^^^^^^^^^^^^^^^^^^^^^^^^^^^^^^^^^^^^^^^^^^^^^^^^^^^^^^^^^^
socket.gaierror: [Errno -2] Name or service not known

The above exception was the direct cause of the following exception:

Traceback (most recent call last):
  File "/home/airflow/.local/lib/python3.12/site-packages/urllib3/connectionpool.py", line 789, in urlopen
    response = self._make_request(
               ^^^^^^^^^^^^^^^^^^^
  File "/home/airflow/.local/lib/python3.12/site-packages/urllib3/connectionpool.py", line 495, in _make_request
    conn.request(
  File "/home/airflow/.local/lib/python3.12/site-packages/urllib3/connection.py", line 441, in request
    self.endheaders()
  File "/usr/local/lib/python3.12/http/client.py", line 1331, in endheaders
    self._send_output(message_body, encode_chunked=encode_chunked)
  File "/usr/local/lib/python3.12/http/client.py", line 1091, in _send_output
    self.send(msg)
  File "/usr/local/lib/python3.12/http/client.py", line 1035, in send
    self.connect()
  File "/home/airflow/.local/lib/python3.12/site-packages/urllib3/connection.py", line 279, in connect
    self.sock = self._new_conn()
                ^^^^^^^^^^^^^^^^
  File "/home/airflow/.local/lib/python3.12/site-packages/urllib3/connection.py", line 206, in _new_conn
    raise NameResolutionError(self.host, self, e) from e
urllib3.exceptions.NameResolutionError: <urllib3.connection.HTTPConnection object at 0x7f9e45cb9160>: Failed to resolve 'host.docker.internal' ([Errno -2] Name or service not known)

The above exception was the direct cause of the following exception:

Traceback (most recent call last):
  File "/home/airflow/.local/lib/python3.12/site-packages/requests/adapters.py", line 667, in send
    resp = conn.urlopen(
           ^^^^^^^^^^^^^
  File "/home/airflow/.local/lib/python3.12/site-packages/urllib3/connectionpool.py", line 843, in urlopen
    retries = retries.increment(
              ^^^^^^^^^^^^^^^^^^
  File "/home/airflow/.local/lib/python3.12/site-packages/urllib3/util/retry.py", line 519, in increment
    raise MaxRetryError(_pool, url, reason) from reason  # type: ignore[arg-type]
    ^^^^^^^^^^^^^^^^^^^^^^^^^^^^^^^^^^^^^^^^^^^^^^^^^^^
urllib3.exceptions.MaxRetryError: HTTPConnectionPool(host='host.docker.internal', port=8000): Max retries exceeded with url: /api/simulators/ (Caused by NameResolutionError("<urllib3.connection.HTTPConnection object at 0x7f9e45cb9160>: Failed to resolve 'host.docker.internal' ([Errno -2] Name or service not known)"))

During handling of the above exception, another exception occurred:

Traceback (most recent call last):
  File "/home/airflow/.local/lib/python3.12/site-packages/airflow/models/dagbag.py", line 383, in parse
    loader.exec_module(new_module)
  File "<frozen importlib._bootstrap_external>", line 999, in exec_module
  File "<frozen importlib._bootstrap>", line 488, in _call_with_frames_removed
  File "/opt/airflow/dags/dynamic_dags.py", line 22, in <module>
    simulators = fetch_simulator_instances()
                 ^^^^^^^^^^^^^^^^^^^^^^^^^^^
  File "/opt/airflow/dags/dynamic_dags.py", line 10, in fetch_simulator_instances
    response = requests.get('http://host.docker.internal:8000/api/simulators/')
               ^^^^^^^^^^^^^^^^^^^^^^^^^^^^^^^^^^^^^^^^^^^^^^^^^^^^^^^^^^^^^^^^
  File "/home/airflow/.local/lib/python3.12/site-packages/requests/api.py", line 73, in get
    return request("get", url, params=params, **kwargs)
           ^^^^^^^^^^^^^^^^^^^^^^^^^^^^^^^^^^^^^^^^^^^^
  File "/home/airflow/.local/lib/python3.12/site-packages/requests/api.py", line 59, in request
    return session.request(method=method, url=url, **kwargs)
           ^^^^^^^^^^^^^^^^^^^^^^^^^^^^^^^^^^^^^^^^^^^^^^^^^
  File "/home/airflow/.local/lib/python3.12/site-packages/requests/sessions.py", line 589, in request
    resp = self.send(prep, **send_kwargs)
           ^^^^^^^^^^^^^^^^^^^^^^^^^^^^^^
  File "/home/airflow/.local/lib/python3.12/site-packages/requests/sessions.py", line 703, in send
    r = adapter.send(request, **kwargs)
        ^^^^^^^^^^^^^^^^^^^^^^^^^^^^^^^
  File "/home/airflow/.local/lib/python3.12/site-packages/requests/adapters.py", line 700, in send
    raise ConnectionError(e, request=request)
requests.exceptions.ConnectionError: HTTPConnectionPool(host='host.docker.internal', port=8000): Max retries exceeded with url: /api/simulators/ (Caused by NameResolutionError("<urllib3.connection.HTTPConnection object at 0x7f9e45cb9160>: Failed to resolve 'host.docker.internal' ([Errno -2] Name or service not known)"))
[2024-12-24T22:29:16.966+0000] {processor.py:927} WARNING - No viable dags retrieved from /opt/airflow/dags/dynamic_dags.py
[2024-12-24T22:29:16.985+0000] {processor.py:208} INFO - Processing /opt/airflow/dags/dynamic_dags.py took 8.228 seconds
[2024-12-24T22:29:47.550+0000] {processor.py:186} INFO - Started process (PID=474) to work on /opt/airflow/dags/dynamic_dags.py
[2024-12-24T22:29:47.552+0000] {processor.py:914} INFO - Processing file /opt/airflow/dags/dynamic_dags.py for tasks to queue
[2024-12-24T22:29:47.554+0000] {logging_mixin.py:190} INFO - [2024-12-24T22:29:47.554+0000] {dagbag.py:588} INFO - Filling up the DagBag from /opt/airflow/dags/dynamic_dags.py
[2024-12-24T22:29:57.820+0000] {logging_mixin.py:190} INFO - [2024-12-24T22:29:57.802+0000] {dagbag.py:387} ERROR - Failed to import: /opt/airflow/dags/dynamic_dags.py
Traceback (most recent call last):
  File "/home/airflow/.local/lib/python3.12/site-packages/urllib3/connection.py", line 199, in _new_conn
    sock = connection.create_connection(
           ^^^^^^^^^^^^^^^^^^^^^^^^^^^^^
  File "/home/airflow/.local/lib/python3.12/site-packages/urllib3/util/connection.py", line 60, in create_connection
    for res in socket.getaddrinfo(host, port, family, socket.SOCK_STREAM):
               ^^^^^^^^^^^^^^^^^^^^^^^^^^^^^^^^^^^^^^^^^^^^^^^^^^^^^^^^^^
  File "/usr/local/lib/python3.12/socket.py", line 976, in getaddrinfo
    for res in _socket.getaddrinfo(host, port, family, type, proto, flags):
               ^^^^^^^^^^^^^^^^^^^^^^^^^^^^^^^^^^^^^^^^^^^^^^^^^^^^^^^^^^^
socket.gaierror: [Errno -2] Name or service not known

The above exception was the direct cause of the following exception:

Traceback (most recent call last):
  File "/home/airflow/.local/lib/python3.12/site-packages/urllib3/connectionpool.py", line 789, in urlopen
    response = self._make_request(
               ^^^^^^^^^^^^^^^^^^^
  File "/home/airflow/.local/lib/python3.12/site-packages/urllib3/connectionpool.py", line 495, in _make_request
    conn.request(
  File "/home/airflow/.local/lib/python3.12/site-packages/urllib3/connection.py", line 441, in request
    self.endheaders()
  File "/usr/local/lib/python3.12/http/client.py", line 1331, in endheaders
    self._send_output(message_body, encode_chunked=encode_chunked)
  File "/usr/local/lib/python3.12/http/client.py", line 1091, in _send_output
    self.send(msg)
  File "/usr/local/lib/python3.12/http/client.py", line 1035, in send
    self.connect()
  File "/home/airflow/.local/lib/python3.12/site-packages/urllib3/connection.py", line 279, in connect
    self.sock = self._new_conn()
                ^^^^^^^^^^^^^^^^
  File "/home/airflow/.local/lib/python3.12/site-packages/urllib3/connection.py", line 206, in _new_conn
    raise NameResolutionError(self.host, self, e) from e
urllib3.exceptions.NameResolutionError: <urllib3.connection.HTTPConnection object at 0x7f9e45cb86e0>: Failed to resolve 'host.docker.internal' ([Errno -2] Name or service not known)

The above exception was the direct cause of the following exception:

Traceback (most recent call last):
  File "/home/airflow/.local/lib/python3.12/site-packages/requests/adapters.py", line 667, in send
    resp = conn.urlopen(
           ^^^^^^^^^^^^^
  File "/home/airflow/.local/lib/python3.12/site-packages/urllib3/connectionpool.py", line 843, in urlopen
    retries = retries.increment(
              ^^^^^^^^^^^^^^^^^^
  File "/home/airflow/.local/lib/python3.12/site-packages/urllib3/util/retry.py", line 519, in increment
    raise MaxRetryError(_pool, url, reason) from reason  # type: ignore[arg-type]
    ^^^^^^^^^^^^^^^^^^^^^^^^^^^^^^^^^^^^^^^^^^^^^^^^^^^
urllib3.exceptions.MaxRetryError: HTTPConnectionPool(host='host.docker.internal', port=8000): Max retries exceeded with url: /api/simulators/ (Caused by NameResolutionError("<urllib3.connection.HTTPConnection object at 0x7f9e45cb86e0>: Failed to resolve 'host.docker.internal' ([Errno -2] Name or service not known)"))

During handling of the above exception, another exception occurred:

Traceback (most recent call last):
  File "/home/airflow/.local/lib/python3.12/site-packages/airflow/models/dagbag.py", line 383, in parse
    loader.exec_module(new_module)
  File "<frozen importlib._bootstrap_external>", line 999, in exec_module
  File "<frozen importlib._bootstrap>", line 488, in _call_with_frames_removed
  File "/opt/airflow/dags/dynamic_dags.py", line 22, in <module>
    simulators = fetch_simulator_instances()
                 ^^^^^^^^^^^^^^^^^^^^^^^^^^^
  File "/opt/airflow/dags/dynamic_dags.py", line 10, in fetch_simulator_instances
    response = requests.get('http://host.docker.internal:8000/api/simulators/')
               ^^^^^^^^^^^^^^^^^^^^^^^^^^^^^^^^^^^^^^^^^^^^^^^^^^^^^^^^^^^^^^^^
  File "/home/airflow/.local/lib/python3.12/site-packages/requests/api.py", line 73, in get
    return request("get", url, params=params, **kwargs)
           ^^^^^^^^^^^^^^^^^^^^^^^^^^^^^^^^^^^^^^^^^^^^
  File "/home/airflow/.local/lib/python3.12/site-packages/requests/api.py", line 59, in request
    return session.request(method=method, url=url, **kwargs)
           ^^^^^^^^^^^^^^^^^^^^^^^^^^^^^^^^^^^^^^^^^^^^^^^^^
  File "/home/airflow/.local/lib/python3.12/site-packages/requests/sessions.py", line 589, in request
    resp = self.send(prep, **send_kwargs)
           ^^^^^^^^^^^^^^^^^^^^^^^^^^^^^^
  File "/home/airflow/.local/lib/python3.12/site-packages/requests/sessions.py", line 703, in send
    r = adapter.send(request, **kwargs)
        ^^^^^^^^^^^^^^^^^^^^^^^^^^^^^^^
  File "/home/airflow/.local/lib/python3.12/site-packages/requests/adapters.py", line 700, in send
    raise ConnectionError(e, request=request)
requests.exceptions.ConnectionError: HTTPConnectionPool(host='host.docker.internal', port=8000): Max retries exceeded with url: /api/simulators/ (Caused by NameResolutionError("<urllib3.connection.HTTPConnection object at 0x7f9e45cb86e0>: Failed to resolve 'host.docker.internal' ([Errno -2] Name or service not known)"))
[2024-12-24T22:29:57.823+0000] {processor.py:927} WARNING - No viable dags retrieved from /opt/airflow/dags/dynamic_dags.py
[2024-12-24T22:29:57.844+0000] {processor.py:208} INFO - Processing /opt/airflow/dags/dynamic_dags.py took 8.164 seconds
[2024-12-24T22:30:28.000+0000] {processor.py:186} INFO - Started process (PID=575) to work on /opt/airflow/dags/dynamic_dags.py
[2024-12-24T22:30:28.003+0000] {processor.py:914} INFO - Processing file /opt/airflow/dags/dynamic_dags.py for tasks to queue
[2024-12-24T22:30:28.005+0000] {logging_mixin.py:190} INFO - [2024-12-24T22:30:28.005+0000] {dagbag.py:588} INFO - Filling up the DagBag from /opt/airflow/dags/dynamic_dags.py
[2024-12-24T22:30:50.367+0000] {processor.py:186} INFO - Started process (PID=59) to work on /opt/airflow/dags/dynamic_dags.py
[2024-12-24T22:30:50.369+0000] {processor.py:914} INFO - Processing file /opt/airflow/dags/dynamic_dags.py for tasks to queue
[2024-12-24T22:30:50.371+0000] {logging_mixin.py:190} INFO - [2024-12-24T22:30:50.371+0000] {dagbag.py:588} INFO - Filling up the DagBag from /opt/airflow/dags/dynamic_dags.py
[2024-12-24T22:31:00.613+0000] {logging_mixin.py:190} INFO - [2024-12-24T22:31:00.601+0000] {dagbag.py:387} ERROR - Failed to import: /opt/airflow/dags/dynamic_dags.py
Traceback (most recent call last):
  File "/home/airflow/.local/lib/python3.12/site-packages/urllib3/connection.py", line 199, in _new_conn
    sock = connection.create_connection(
           ^^^^^^^^^^^^^^^^^^^^^^^^^^^^^
  File "/home/airflow/.local/lib/python3.12/site-packages/urllib3/util/connection.py", line 60, in create_connection
    for res in socket.getaddrinfo(host, port, family, socket.SOCK_STREAM):
               ^^^^^^^^^^^^^^^^^^^^^^^^^^^^^^^^^^^^^^^^^^^^^^^^^^^^^^^^^^
  File "/usr/local/lib/python3.12/socket.py", line 976, in getaddrinfo
    for res in _socket.getaddrinfo(host, port, family, type, proto, flags):
               ^^^^^^^^^^^^^^^^^^^^^^^^^^^^^^^^^^^^^^^^^^^^^^^^^^^^^^^^^^^
socket.gaierror: [Errno -2] Name or service not known

The above exception was the direct cause of the following exception:

Traceback (most recent call last):
  File "/home/airflow/.local/lib/python3.12/site-packages/urllib3/connectionpool.py", line 789, in urlopen
    response = self._make_request(
               ^^^^^^^^^^^^^^^^^^^
  File "/home/airflow/.local/lib/python3.12/site-packages/urllib3/connectionpool.py", line 495, in _make_request
    conn.request(
  File "/home/airflow/.local/lib/python3.12/site-packages/urllib3/connection.py", line 441, in request
    self.endheaders()
  File "/usr/local/lib/python3.12/http/client.py", line 1331, in endheaders
    self._send_output(message_body, encode_chunked=encode_chunked)
  File "/usr/local/lib/python3.12/http/client.py", line 1091, in _send_output
    self.send(msg)
  File "/usr/local/lib/python3.12/http/client.py", line 1035, in send
    self.connect()
  File "/home/airflow/.local/lib/python3.12/site-packages/urllib3/connection.py", line 279, in connect
    self.sock = self._new_conn()
                ^^^^^^^^^^^^^^^^
  File "/home/airflow/.local/lib/python3.12/site-packages/urllib3/connection.py", line 206, in _new_conn
    raise NameResolutionError(self.host, self, e) from e
urllib3.exceptions.NameResolutionError: <urllib3.connection.HTTPConnection object at 0x7fd6b074d4f0>: Failed to resolve 'host.docker.internal' ([Errno -2] Name or service not known)

The above exception was the direct cause of the following exception:

Traceback (most recent call last):
  File "/home/airflow/.local/lib/python3.12/site-packages/requests/adapters.py", line 667, in send
    resp = conn.urlopen(
           ^^^^^^^^^^^^^
  File "/home/airflow/.local/lib/python3.12/site-packages/urllib3/connectionpool.py", line 843, in urlopen
    retries = retries.increment(
              ^^^^^^^^^^^^^^^^^^
  File "/home/airflow/.local/lib/python3.12/site-packages/urllib3/util/retry.py", line 519, in increment
    raise MaxRetryError(_pool, url, reason) from reason  # type: ignore[arg-type]
    ^^^^^^^^^^^^^^^^^^^^^^^^^^^^^^^^^^^^^^^^^^^^^^^^^^^
urllib3.exceptions.MaxRetryError: HTTPConnectionPool(host='host.docker.internal', port=8000): Max retries exceeded with url: /api/simulators/ (Caused by NameResolutionError("<urllib3.connection.HTTPConnection object at 0x7fd6b074d4f0>: Failed to resolve 'host.docker.internal' ([Errno -2] Name or service not known)"))

During handling of the above exception, another exception occurred:

Traceback (most recent call last):
  File "/home/airflow/.local/lib/python3.12/site-packages/airflow/models/dagbag.py", line 383, in parse
    loader.exec_module(new_module)
  File "<frozen importlib._bootstrap_external>", line 999, in exec_module
  File "<frozen importlib._bootstrap>", line 488, in _call_with_frames_removed
  File "/opt/airflow/dags/dynamic_dags.py", line 22, in <module>
    simulators = fetch_simulator_instances()
                 ^^^^^^^^^^^^^^^^^^^^^^^^^^^
  File "/opt/airflow/dags/dynamic_dags.py", line 10, in fetch_simulator_instances
    response = requests.get('http://host.docker.internal:8000/api/simulators/')
               ^^^^^^^^^^^^^^^^^^^^^^^^^^^^^^^^^^^^^^^^^^^^^^^^^^^^^^^^^^^^^^^^
  File "/home/airflow/.local/lib/python3.12/site-packages/requests/api.py", line 73, in get
    return request("get", url, params=params, **kwargs)
           ^^^^^^^^^^^^^^^^^^^^^^^^^^^^^^^^^^^^^^^^^^^^
  File "/home/airflow/.local/lib/python3.12/site-packages/requests/api.py", line 59, in request
    return session.request(method=method, url=url, **kwargs)
           ^^^^^^^^^^^^^^^^^^^^^^^^^^^^^^^^^^^^^^^^^^^^^^^^^
  File "/home/airflow/.local/lib/python3.12/site-packages/requests/sessions.py", line 589, in request
    resp = self.send(prep, **send_kwargs)
           ^^^^^^^^^^^^^^^^^^^^^^^^^^^^^^
  File "/home/airflow/.local/lib/python3.12/site-packages/requests/sessions.py", line 703, in send
    r = adapter.send(request, **kwargs)
        ^^^^^^^^^^^^^^^^^^^^^^^^^^^^^^^
  File "/home/airflow/.local/lib/python3.12/site-packages/requests/adapters.py", line 700, in send
    raise ConnectionError(e, request=request)
requests.exceptions.ConnectionError: HTTPConnectionPool(host='host.docker.internal', port=8000): Max retries exceeded with url: /api/simulators/ (Caused by NameResolutionError("<urllib3.connection.HTTPConnection object at 0x7fd6b074d4f0>: Failed to resolve 'host.docker.internal' ([Errno -2] Name or service not known)"))
[2024-12-24T22:31:00.615+0000] {processor.py:927} WARNING - No viable dags retrieved from /opt/airflow/dags/dynamic_dags.py
[2024-12-24T22:31:00.651+0000] {processor.py:208} INFO - Processing /opt/airflow/dags/dynamic_dags.py took 8.142 seconds
[2024-12-24T22:32:16.432+0000] {processor.py:186} INFO - Started process (PID=66) to work on /opt/airflow/dags/dynamic_dags.py
[2024-12-24T22:32:16.434+0000] {processor.py:914} INFO - Processing file /opt/airflow/dags/dynamic_dags.py for tasks to queue
[2024-12-24T22:32:16.437+0000] {logging_mixin.py:190} INFO - [2024-12-24T22:32:16.437+0000] {dagbag.py:588} INFO - Filling up the DagBag from /opt/airflow/dags/dynamic_dags.py
[2024-12-24T22:32:24.540+0000] {logging_mixin.py:190} INFO - [2024-12-24T22:32:24.530+0000] {dagbag.py:387} ERROR - Failed to import: /opt/airflow/dags/dynamic_dags.py
Traceback (most recent call last):
  File "/home/airflow/.local/lib/python3.12/site-packages/urllib3/connection.py", line 199, in _new_conn
    sock = connection.create_connection(
           ^^^^^^^^^^^^^^^^^^^^^^^^^^^^^
  File "/home/airflow/.local/lib/python3.12/site-packages/urllib3/util/connection.py", line 60, in create_connection
    for res in socket.getaddrinfo(host, port, family, socket.SOCK_STREAM):
               ^^^^^^^^^^^^^^^^^^^^^^^^^^^^^^^^^^^^^^^^^^^^^^^^^^^^^^^^^^
  File "/usr/local/lib/python3.12/socket.py", line 976, in getaddrinfo
    for res in _socket.getaddrinfo(host, port, family, type, proto, flags):
               ^^^^^^^^^^^^^^^^^^^^^^^^^^^^^^^^^^^^^^^^^^^^^^^^^^^^^^^^^^^
socket.gaierror: [Errno -2] Name or service not known

The above exception was the direct cause of the following exception:

Traceback (most recent call last):
  File "/home/airflow/.local/lib/python3.12/site-packages/urllib3/connectionpool.py", line 789, in urlopen
    response = self._make_request(
               ^^^^^^^^^^^^^^^^^^^
  File "/home/airflow/.local/lib/python3.12/site-packages/urllib3/connectionpool.py", line 495, in _make_request
    conn.request(
  File "/home/airflow/.local/lib/python3.12/site-packages/urllib3/connection.py", line 441, in request
    self.endheaders()
  File "/usr/local/lib/python3.12/http/client.py", line 1331, in endheaders
    self._send_output(message_body, encode_chunked=encode_chunked)
  File "/usr/local/lib/python3.12/http/client.py", line 1091, in _send_output
    self.send(msg)
  File "/usr/local/lib/python3.12/http/client.py", line 1035, in send
    self.connect()
  File "/home/airflow/.local/lib/python3.12/site-packages/urllib3/connection.py", line 279, in connect
    self.sock = self._new_conn()
                ^^^^^^^^^^^^^^^^
  File "/home/airflow/.local/lib/python3.12/site-packages/urllib3/connection.py", line 206, in _new_conn
    raise NameResolutionError(self.host, self, e) from e
urllib3.exceptions.NameResolutionError: <urllib3.connection.HTTPConnection object at 0x7ff594f64ec0>: Failed to resolve 'host.docker.internal' ([Errno -2] Name or service not known)

The above exception was the direct cause of the following exception:

Traceback (most recent call last):
  File "/home/airflow/.local/lib/python3.12/site-packages/requests/adapters.py", line 667, in send
    resp = conn.urlopen(
           ^^^^^^^^^^^^^
  File "/home/airflow/.local/lib/python3.12/site-packages/urllib3/connectionpool.py", line 843, in urlopen
    retries = retries.increment(
              ^^^^^^^^^^^^^^^^^^
  File "/home/airflow/.local/lib/python3.12/site-packages/urllib3/util/retry.py", line 519, in increment
    raise MaxRetryError(_pool, url, reason) from reason  # type: ignore[arg-type]
    ^^^^^^^^^^^^^^^^^^^^^^^^^^^^^^^^^^^^^^^^^^^^^^^^^^^
urllib3.exceptions.MaxRetryError: HTTPConnectionPool(host='host.docker.internal', port=8000): Max retries exceeded with url: /api/simulators/ (Caused by NameResolutionError("<urllib3.connection.HTTPConnection object at 0x7ff594f64ec0>: Failed to resolve 'host.docker.internal' ([Errno -2] Name or service not known)"))

During handling of the above exception, another exception occurred:

Traceback (most recent call last):
  File "/home/airflow/.local/lib/python3.12/site-packages/airflow/models/dagbag.py", line 383, in parse
    loader.exec_module(new_module)
  File "<frozen importlib._bootstrap_external>", line 999, in exec_module
  File "<frozen importlib._bootstrap>", line 488, in _call_with_frames_removed
  File "/opt/airflow/dags/dynamic_dags.py", line 22, in <module>
    simulators = fetch_simulator_instances()
                 ^^^^^^^^^^^^^^^^^^^^^^^^^^^
  File "/opt/airflow/dags/dynamic_dags.py", line 10, in fetch_simulator_instances
    response = requests.get('http://host.docker.internal:8000/api/simulators/')
               ^^^^^^^^^^^^^^^^^^^^^^^^^^^^^^^^^^^^^^^^^^^^^^^^^^^^^^^^^^^^^^^^
  File "/home/airflow/.local/lib/python3.12/site-packages/requests/api.py", line 73, in get
    return request("get", url, params=params, **kwargs)
           ^^^^^^^^^^^^^^^^^^^^^^^^^^^^^^^^^^^^^^^^^^^^
  File "/home/airflow/.local/lib/python3.12/site-packages/requests/api.py", line 59, in request
    return session.request(method=method, url=url, **kwargs)
           ^^^^^^^^^^^^^^^^^^^^^^^^^^^^^^^^^^^^^^^^^^^^^^^^^
  File "/home/airflow/.local/lib/python3.12/site-packages/requests/sessions.py", line 589, in request
    resp = self.send(prep, **send_kwargs)
           ^^^^^^^^^^^^^^^^^^^^^^^^^^^^^^
  File "/home/airflow/.local/lib/python3.12/site-packages/requests/sessions.py", line 703, in send
    r = adapter.send(request, **kwargs)
        ^^^^^^^^^^^^^^^^^^^^^^^^^^^^^^^
  File "/home/airflow/.local/lib/python3.12/site-packages/requests/adapters.py", line 700, in send
    raise ConnectionError(e, request=request)
requests.exceptions.ConnectionError: HTTPConnectionPool(host='host.docker.internal', port=8000): Max retries exceeded with url: /api/simulators/ (Caused by NameResolutionError("<urllib3.connection.HTTPConnection object at 0x7ff594f64ec0>: Failed to resolve 'host.docker.internal' ([Errno -2] Name or service not known)"))
[2024-12-24T22:32:24.542+0000] {processor.py:927} WARNING - No viable dags retrieved from /opt/airflow/dags/dynamic_dags.py
[2024-12-24T22:32:24.558+0000] {processor.py:208} INFO - Processing /opt/airflow/dags/dynamic_dags.py took 8.134 seconds
[2024-12-24T22:32:54.691+0000] {processor.py:186} INFO - Started process (PID=174) to work on /opt/airflow/dags/dynamic_dags.py
[2024-12-24T22:32:54.694+0000] {processor.py:914} INFO - Processing file /opt/airflow/dags/dynamic_dags.py for tasks to queue
[2024-12-24T22:32:54.697+0000] {logging_mixin.py:190} INFO - [2024-12-24T22:32:54.696+0000] {dagbag.py:588} INFO - Filling up the DagBag from /opt/airflow/dags/dynamic_dags.py
[2024-12-24T22:33:02.816+0000] {logging_mixin.py:190} INFO - [2024-12-24T22:33:02.808+0000] {dagbag.py:387} ERROR - Failed to import: /opt/airflow/dags/dynamic_dags.py
Traceback (most recent call last):
  File "/home/airflow/.local/lib/python3.12/site-packages/urllib3/connection.py", line 199, in _new_conn
    sock = connection.create_connection(
           ^^^^^^^^^^^^^^^^^^^^^^^^^^^^^
  File "/home/airflow/.local/lib/python3.12/site-packages/urllib3/util/connection.py", line 60, in create_connection
    for res in socket.getaddrinfo(host, port, family, socket.SOCK_STREAM):
               ^^^^^^^^^^^^^^^^^^^^^^^^^^^^^^^^^^^^^^^^^^^^^^^^^^^^^^^^^^
  File "/usr/local/lib/python3.12/socket.py", line 976, in getaddrinfo
    for res in _socket.getaddrinfo(host, port, family, type, proto, flags):
               ^^^^^^^^^^^^^^^^^^^^^^^^^^^^^^^^^^^^^^^^^^^^^^^^^^^^^^^^^^^
socket.gaierror: [Errno -2] Name or service not known

The above exception was the direct cause of the following exception:

Traceback (most recent call last):
  File "/home/airflow/.local/lib/python3.12/site-packages/urllib3/connectionpool.py", line 789, in urlopen
    response = self._make_request(
               ^^^^^^^^^^^^^^^^^^^
  File "/home/airflow/.local/lib/python3.12/site-packages/urllib3/connectionpool.py", line 495, in _make_request
    conn.request(
  File "/home/airflow/.local/lib/python3.12/site-packages/urllib3/connection.py", line 441, in request
    self.endheaders()
  File "/usr/local/lib/python3.12/http/client.py", line 1331, in endheaders
    self._send_output(message_body, encode_chunked=encode_chunked)
  File "/usr/local/lib/python3.12/http/client.py", line 1091, in _send_output
    self.send(msg)
  File "/usr/local/lib/python3.12/http/client.py", line 1035, in send
    self.connect()
  File "/home/airflow/.local/lib/python3.12/site-packages/urllib3/connection.py", line 279, in connect
    self.sock = self._new_conn()
                ^^^^^^^^^^^^^^^^
  File "/home/airflow/.local/lib/python3.12/site-packages/urllib3/connection.py", line 206, in _new_conn
    raise NameResolutionError(self.host, self, e) from e
urllib3.exceptions.NameResolutionError: <urllib3.connection.HTTPConnection object at 0x7ff594bf2ff0>: Failed to resolve 'host.docker.internal' ([Errno -2] Name or service not known)

The above exception was the direct cause of the following exception:

Traceback (most recent call last):
  File "/home/airflow/.local/lib/python3.12/site-packages/requests/adapters.py", line 667, in send
    resp = conn.urlopen(
           ^^^^^^^^^^^^^
  File "/home/airflow/.local/lib/python3.12/site-packages/urllib3/connectionpool.py", line 843, in urlopen
    retries = retries.increment(
              ^^^^^^^^^^^^^^^^^^
  File "/home/airflow/.local/lib/python3.12/site-packages/urllib3/util/retry.py", line 519, in increment
    raise MaxRetryError(_pool, url, reason) from reason  # type: ignore[arg-type]
    ^^^^^^^^^^^^^^^^^^^^^^^^^^^^^^^^^^^^^^^^^^^^^^^^^^^
urllib3.exceptions.MaxRetryError: HTTPConnectionPool(host='host.docker.internal', port=8000): Max retries exceeded with url: /api/simulators/ (Caused by NameResolutionError("<urllib3.connection.HTTPConnection object at 0x7ff594bf2ff0>: Failed to resolve 'host.docker.internal' ([Errno -2] Name or service not known)"))

During handling of the above exception, another exception occurred:

Traceback (most recent call last):
  File "/home/airflow/.local/lib/python3.12/site-packages/airflow/models/dagbag.py", line 383, in parse
    loader.exec_module(new_module)
  File "<frozen importlib._bootstrap_external>", line 999, in exec_module
  File "<frozen importlib._bootstrap>", line 488, in _call_with_frames_removed
  File "/opt/airflow/dags/dynamic_dags.py", line 22, in <module>
    simulators = fetch_simulator_instances()
                 ^^^^^^^^^^^^^^^^^^^^^^^^^^^
  File "/opt/airflow/dags/dynamic_dags.py", line 10, in fetch_simulator_instances
    response = requests.get('http://host.docker.internal:8000/api/simulators/')
               ^^^^^^^^^^^^^^^^^^^^^^^^^^^^^^^^^^^^^^^^^^^^^^^^^^^^^^^^^^^^^^^^
  File "/home/airflow/.local/lib/python3.12/site-packages/requests/api.py", line 73, in get
    return request("get", url, params=params, **kwargs)
           ^^^^^^^^^^^^^^^^^^^^^^^^^^^^^^^^^^^^^^^^^^^^
  File "/home/airflow/.local/lib/python3.12/site-packages/requests/api.py", line 59, in request
    return session.request(method=method, url=url, **kwargs)
           ^^^^^^^^^^^^^^^^^^^^^^^^^^^^^^^^^^^^^^^^^^^^^^^^^
  File "/home/airflow/.local/lib/python3.12/site-packages/requests/sessions.py", line 589, in request
    resp = self.send(prep, **send_kwargs)
           ^^^^^^^^^^^^^^^^^^^^^^^^^^^^^^
  File "/home/airflow/.local/lib/python3.12/site-packages/requests/sessions.py", line 703, in send
    r = adapter.send(request, **kwargs)
        ^^^^^^^^^^^^^^^^^^^^^^^^^^^^^^^
  File "/home/airflow/.local/lib/python3.12/site-packages/requests/adapters.py", line 700, in send
    raise ConnectionError(e, request=request)
requests.exceptions.ConnectionError: HTTPConnectionPool(host='host.docker.internal', port=8000): Max retries exceeded with url: /api/simulators/ (Caused by NameResolutionError("<urllib3.connection.HTTPConnection object at 0x7ff594bf2ff0>: Failed to resolve 'host.docker.internal' ([Errno -2] Name or service not known)"))
[2024-12-24T22:33:02.818+0000] {processor.py:927} WARNING - No viable dags retrieved from /opt/airflow/dags/dynamic_dags.py
[2024-12-24T22:33:02.833+0000] {processor.py:208} INFO - Processing /opt/airflow/dags/dynamic_dags.py took 8.151 seconds
[2024-12-24T22:33:33.786+0000] {processor.py:186} INFO - Started process (PID=258) to work on /opt/airflow/dags/dynamic_dags.py
[2024-12-24T22:33:33.788+0000] {processor.py:914} INFO - Processing file /opt/airflow/dags/dynamic_dags.py for tasks to queue
[2024-12-24T22:33:33.792+0000] {logging_mixin.py:190} INFO - [2024-12-24T22:33:33.792+0000] {dagbag.py:588} INFO - Filling up the DagBag from /opt/airflow/dags/dynamic_dags.py
[2024-12-24T22:33:41.903+0000] {logging_mixin.py:190} INFO - [2024-12-24T22:33:41.891+0000] {dagbag.py:387} ERROR - Failed to import: /opt/airflow/dags/dynamic_dags.py
Traceback (most recent call last):
  File "/home/airflow/.local/lib/python3.12/site-packages/urllib3/connection.py", line 199, in _new_conn
    sock = connection.create_connection(
           ^^^^^^^^^^^^^^^^^^^^^^^^^^^^^
  File "/home/airflow/.local/lib/python3.12/site-packages/urllib3/util/connection.py", line 60, in create_connection
    for res in socket.getaddrinfo(host, port, family, socket.SOCK_STREAM):
               ^^^^^^^^^^^^^^^^^^^^^^^^^^^^^^^^^^^^^^^^^^^^^^^^^^^^^^^^^^
  File "/usr/local/lib/python3.12/socket.py", line 976, in getaddrinfo
    for res in _socket.getaddrinfo(host, port, family, type, proto, flags):
               ^^^^^^^^^^^^^^^^^^^^^^^^^^^^^^^^^^^^^^^^^^^^^^^^^^^^^^^^^^^
socket.gaierror: [Errno -2] Name or service not known

The above exception was the direct cause of the following exception:

Traceback (most recent call last):
  File "/home/airflow/.local/lib/python3.12/site-packages/urllib3/connectionpool.py", line 789, in urlopen
    response = self._make_request(
               ^^^^^^^^^^^^^^^^^^^
  File "/home/airflow/.local/lib/python3.12/site-packages/urllib3/connectionpool.py", line 495, in _make_request
    conn.request(
  File "/home/airflow/.local/lib/python3.12/site-packages/urllib3/connection.py", line 441, in request
    self.endheaders()
  File "/usr/local/lib/python3.12/http/client.py", line 1331, in endheaders
    self._send_output(message_body, encode_chunked=encode_chunked)
  File "/usr/local/lib/python3.12/http/client.py", line 1091, in _send_output
    self.send(msg)
  File "/usr/local/lib/python3.12/http/client.py", line 1035, in send
    self.connect()
  File "/home/airflow/.local/lib/python3.12/site-packages/urllib3/connection.py", line 279, in connect
    self.sock = self._new_conn()
                ^^^^^^^^^^^^^^^^
  File "/home/airflow/.local/lib/python3.12/site-packages/urllib3/connection.py", line 206, in _new_conn
    raise NameResolutionError(self.host, self, e) from e
urllib3.exceptions.NameResolutionError: <urllib3.connection.HTTPConnection object at 0x7ff594cad1f0>: Failed to resolve 'host.docker.internal' ([Errno -2] Name or service not known)

The above exception was the direct cause of the following exception:

Traceback (most recent call last):
  File "/home/airflow/.local/lib/python3.12/site-packages/requests/adapters.py", line 667, in send
    resp = conn.urlopen(
           ^^^^^^^^^^^^^
  File "/home/airflow/.local/lib/python3.12/site-packages/urllib3/connectionpool.py", line 843, in urlopen
    retries = retries.increment(
              ^^^^^^^^^^^^^^^^^^
  File "/home/airflow/.local/lib/python3.12/site-packages/urllib3/util/retry.py", line 519, in increment
    raise MaxRetryError(_pool, url, reason) from reason  # type: ignore[arg-type]
    ^^^^^^^^^^^^^^^^^^^^^^^^^^^^^^^^^^^^^^^^^^^^^^^^^^^
urllib3.exceptions.MaxRetryError: HTTPConnectionPool(host='host.docker.internal', port=8000): Max retries exceeded with url: /api/simulators/ (Caused by NameResolutionError("<urllib3.connection.HTTPConnection object at 0x7ff594cad1f0>: Failed to resolve 'host.docker.internal' ([Errno -2] Name or service not known)"))

During handling of the above exception, another exception occurred:

Traceback (most recent call last):
  File "/home/airflow/.local/lib/python3.12/site-packages/airflow/models/dagbag.py", line 383, in parse
    loader.exec_module(new_module)
  File "<frozen importlib._bootstrap_external>", line 999, in exec_module
  File "<frozen importlib._bootstrap>", line 488, in _call_with_frames_removed
  File "/opt/airflow/dags/dynamic_dags.py", line 22, in <module>
    simulators = fetch_simulator_instances()
                 ^^^^^^^^^^^^^^^^^^^^^^^^^^^
  File "/opt/airflow/dags/dynamic_dags.py", line 10, in fetch_simulator_instances
    response = requests.get('http://host.docker.internal:8000/api/simulators/')
               ^^^^^^^^^^^^^^^^^^^^^^^^^^^^^^^^^^^^^^^^^^^^^^^^^^^^^^^^^^^^^^^^
  File "/home/airflow/.local/lib/python3.12/site-packages/requests/api.py", line 73, in get
    return request("get", url, params=params, **kwargs)
           ^^^^^^^^^^^^^^^^^^^^^^^^^^^^^^^^^^^^^^^^^^^^
  File "/home/airflow/.local/lib/python3.12/site-packages/requests/api.py", line 59, in request
    return session.request(method=method, url=url, **kwargs)
           ^^^^^^^^^^^^^^^^^^^^^^^^^^^^^^^^^^^^^^^^^^^^^^^^^
  File "/home/airflow/.local/lib/python3.12/site-packages/requests/sessions.py", line 589, in request
    resp = self.send(prep, **send_kwargs)
           ^^^^^^^^^^^^^^^^^^^^^^^^^^^^^^
  File "/home/airflow/.local/lib/python3.12/site-packages/requests/sessions.py", line 703, in send
    r = adapter.send(request, **kwargs)
        ^^^^^^^^^^^^^^^^^^^^^^^^^^^^^^^
  File "/home/airflow/.local/lib/python3.12/site-packages/requests/adapters.py", line 700, in send
    raise ConnectionError(e, request=request)
requests.exceptions.ConnectionError: HTTPConnectionPool(host='host.docker.internal', port=8000): Max retries exceeded with url: /api/simulators/ (Caused by NameResolutionError("<urllib3.connection.HTTPConnection object at 0x7ff594cad1f0>: Failed to resolve 'host.docker.internal' ([Errno -2] Name or service not known)"))
[2024-12-24T22:33:41.906+0000] {processor.py:927} WARNING - No viable dags retrieved from /opt/airflow/dags/dynamic_dags.py
[2024-12-24T22:33:41.927+0000] {processor.py:208} INFO - Processing /opt/airflow/dags/dynamic_dags.py took 8.145 seconds
[2024-12-24T22:34:12.224+0000] {processor.py:186} INFO - Started process (PID=322) to work on /opt/airflow/dags/dynamic_dags.py
[2024-12-24T22:34:12.226+0000] {processor.py:914} INFO - Processing file /opt/airflow/dags/dynamic_dags.py for tasks to queue
[2024-12-24T22:34:12.228+0000] {logging_mixin.py:190} INFO - [2024-12-24T22:34:12.228+0000] {dagbag.py:588} INFO - Filling up the DagBag from /opt/airflow/dags/dynamic_dags.py
[2024-12-24T22:34:20.341+0000] {logging_mixin.py:190} INFO - [2024-12-24T22:34:20.321+0000] {dagbag.py:387} ERROR - Failed to import: /opt/airflow/dags/dynamic_dags.py
Traceback (most recent call last):
  File "/home/airflow/.local/lib/python3.12/site-packages/urllib3/connection.py", line 199, in _new_conn
    sock = connection.create_connection(
           ^^^^^^^^^^^^^^^^^^^^^^^^^^^^^
  File "/home/airflow/.local/lib/python3.12/site-packages/urllib3/util/connection.py", line 60, in create_connection
    for res in socket.getaddrinfo(host, port, family, socket.SOCK_STREAM):
               ^^^^^^^^^^^^^^^^^^^^^^^^^^^^^^^^^^^^^^^^^^^^^^^^^^^^^^^^^^
  File "/usr/local/lib/python3.12/socket.py", line 976, in getaddrinfo
    for res in _socket.getaddrinfo(host, port, family, type, proto, flags):
               ^^^^^^^^^^^^^^^^^^^^^^^^^^^^^^^^^^^^^^^^^^^^^^^^^^^^^^^^^^^
socket.gaierror: [Errno -2] Name or service not known

The above exception was the direct cause of the following exception:

Traceback (most recent call last):
  File "/home/airflow/.local/lib/python3.12/site-packages/urllib3/connectionpool.py", line 789, in urlopen
    response = self._make_request(
               ^^^^^^^^^^^^^^^^^^^
  File "/home/airflow/.local/lib/python3.12/site-packages/urllib3/connectionpool.py", line 495, in _make_request
    conn.request(
  File "/home/airflow/.local/lib/python3.12/site-packages/urllib3/connection.py", line 441, in request
    self.endheaders()
  File "/usr/local/lib/python3.12/http/client.py", line 1331, in endheaders
    self._send_output(message_body, encode_chunked=encode_chunked)
  File "/usr/local/lib/python3.12/http/client.py", line 1091, in _send_output
    self.send(msg)
  File "/usr/local/lib/python3.12/http/client.py", line 1035, in send
    self.connect()
  File "/home/airflow/.local/lib/python3.12/site-packages/urllib3/connection.py", line 279, in connect
    self.sock = self._new_conn()
                ^^^^^^^^^^^^^^^^
  File "/home/airflow/.local/lib/python3.12/site-packages/urllib3/connection.py", line 206, in _new_conn
    raise NameResolutionError(self.host, self, e) from e
urllib3.exceptions.NameResolutionError: <urllib3.connection.HTTPConnection object at 0x7ff594f65ee0>: Failed to resolve 'host.docker.internal' ([Errno -2] Name or service not known)

The above exception was the direct cause of the following exception:

Traceback (most recent call last):
  File "/home/airflow/.local/lib/python3.12/site-packages/requests/adapters.py", line 667, in send
    resp = conn.urlopen(
           ^^^^^^^^^^^^^
  File "/home/airflow/.local/lib/python3.12/site-packages/urllib3/connectionpool.py", line 843, in urlopen
    retries = retries.increment(
              ^^^^^^^^^^^^^^^^^^
  File "/home/airflow/.local/lib/python3.12/site-packages/urllib3/util/retry.py", line 519, in increment
    raise MaxRetryError(_pool, url, reason) from reason  # type: ignore[arg-type]
    ^^^^^^^^^^^^^^^^^^^^^^^^^^^^^^^^^^^^^^^^^^^^^^^^^^^
urllib3.exceptions.MaxRetryError: HTTPConnectionPool(host='host.docker.internal', port=8000): Max retries exceeded with url: /api/simulators/ (Caused by NameResolutionError("<urllib3.connection.HTTPConnection object at 0x7ff594f65ee0>: Failed to resolve 'host.docker.internal' ([Errno -2] Name or service not known)"))

During handling of the above exception, another exception occurred:

Traceback (most recent call last):
  File "/home/airflow/.local/lib/python3.12/site-packages/airflow/models/dagbag.py", line 383, in parse
    loader.exec_module(new_module)
  File "<frozen importlib._bootstrap_external>", line 999, in exec_module
  File "<frozen importlib._bootstrap>", line 488, in _call_with_frames_removed
  File "/opt/airflow/dags/dynamic_dags.py", line 22, in <module>
    simulators = fetch_simulator_instances()
                 ^^^^^^^^^^^^^^^^^^^^^^^^^^^
  File "/opt/airflow/dags/dynamic_dags.py", line 10, in fetch_simulator_instances
    response = requests.get('http://host.docker.internal:8000/api/simulators/')
               ^^^^^^^^^^^^^^^^^^^^^^^^^^^^^^^^^^^^^^^^^^^^^^^^^^^^^^^^^^^^^^^^
  File "/home/airflow/.local/lib/python3.12/site-packages/requests/api.py", line 73, in get
    return request("get", url, params=params, **kwargs)
           ^^^^^^^^^^^^^^^^^^^^^^^^^^^^^^^^^^^^^^^^^^^^
  File "/home/airflow/.local/lib/python3.12/site-packages/requests/api.py", line 59, in request
    return session.request(method=method, url=url, **kwargs)
           ^^^^^^^^^^^^^^^^^^^^^^^^^^^^^^^^^^^^^^^^^^^^^^^^^
  File "/home/airflow/.local/lib/python3.12/site-packages/requests/sessions.py", line 589, in request
    resp = self.send(prep, **send_kwargs)
           ^^^^^^^^^^^^^^^^^^^^^^^^^^^^^^
  File "/home/airflow/.local/lib/python3.12/site-packages/requests/sessions.py", line 703, in send
    r = adapter.send(request, **kwargs)
        ^^^^^^^^^^^^^^^^^^^^^^^^^^^^^^^
  File "/home/airflow/.local/lib/python3.12/site-packages/requests/adapters.py", line 700, in send
    raise ConnectionError(e, request=request)
requests.exceptions.ConnectionError: HTTPConnectionPool(host='host.docker.internal', port=8000): Max retries exceeded with url: /api/simulators/ (Caused by NameResolutionError("<urllib3.connection.HTTPConnection object at 0x7ff594f65ee0>: Failed to resolve 'host.docker.internal' ([Errno -2] Name or service not known)"))
[2024-12-24T22:34:20.344+0000] {processor.py:927} WARNING - No viable dags retrieved from /opt/airflow/dags/dynamic_dags.py
[2024-12-24T22:34:20.372+0000] {processor.py:208} INFO - Processing /opt/airflow/dags/dynamic_dags.py took 8.154 seconds
[2024-12-24T22:34:51.090+0000] {processor.py:186} INFO - Started process (PID=388) to work on /opt/airflow/dags/dynamic_dags.py
[2024-12-24T22:34:51.092+0000] {processor.py:914} INFO - Processing file /opt/airflow/dags/dynamic_dags.py for tasks to queue
[2024-12-24T22:34:51.095+0000] {logging_mixin.py:190} INFO - [2024-12-24T22:34:51.095+0000] {dagbag.py:588} INFO - Filling up the DagBag from /opt/airflow/dags/dynamic_dags.py
[2024-12-24T22:35:01.217+0000] {logging_mixin.py:190} INFO - [2024-12-24T22:35:01.208+0000] {dagbag.py:387} ERROR - Failed to import: /opt/airflow/dags/dynamic_dags.py
Traceback (most recent call last):
  File "/home/airflow/.local/lib/python3.12/site-packages/urllib3/connection.py", line 199, in _new_conn
    sock = connection.create_connection(
           ^^^^^^^^^^^^^^^^^^^^^^^^^^^^^
  File "/home/airflow/.local/lib/python3.12/site-packages/urllib3/util/connection.py", line 60, in create_connection
    for res in socket.getaddrinfo(host, port, family, socket.SOCK_STREAM):
               ^^^^^^^^^^^^^^^^^^^^^^^^^^^^^^^^^^^^^^^^^^^^^^^^^^^^^^^^^^
  File "/usr/local/lib/python3.12/socket.py", line 976, in getaddrinfo
    for res in _socket.getaddrinfo(host, port, family, type, proto, flags):
               ^^^^^^^^^^^^^^^^^^^^^^^^^^^^^^^^^^^^^^^^^^^^^^^^^^^^^^^^^^^
socket.gaierror: [Errno -2] Name or service not known

The above exception was the direct cause of the following exception:

Traceback (most recent call last):
  File "/home/airflow/.local/lib/python3.12/site-packages/urllib3/connectionpool.py", line 789, in urlopen
    response = self._make_request(
               ^^^^^^^^^^^^^^^^^^^
  File "/home/airflow/.local/lib/python3.12/site-packages/urllib3/connectionpool.py", line 495, in _make_request
    conn.request(
  File "/home/airflow/.local/lib/python3.12/site-packages/urllib3/connection.py", line 441, in request
    self.endheaders()
  File "/usr/local/lib/python3.12/http/client.py", line 1331, in endheaders
    self._send_output(message_body, encode_chunked=encode_chunked)
  File "/usr/local/lib/python3.12/http/client.py", line 1091, in _send_output
    self.send(msg)
  File "/usr/local/lib/python3.12/http/client.py", line 1035, in send
    self.connect()
  File "/home/airflow/.local/lib/python3.12/site-packages/urllib3/connection.py", line 279, in connect
    self.sock = self._new_conn()
                ^^^^^^^^^^^^^^^^
  File "/home/airflow/.local/lib/python3.12/site-packages/urllib3/connection.py", line 206, in _new_conn
    raise NameResolutionError(self.host, self, e) from e
urllib3.exceptions.NameResolutionError: <urllib3.connection.HTTPConnection object at 0x7ff5cc5b44d0>: Failed to resolve 'host.docker.internal' ([Errno -2] Name or service not known)

The above exception was the direct cause of the following exception:

Traceback (most recent call last):
  File "/home/airflow/.local/lib/python3.12/site-packages/requests/adapters.py", line 667, in send
    resp = conn.urlopen(
           ^^^^^^^^^^^^^
  File "/home/airflow/.local/lib/python3.12/site-packages/urllib3/connectionpool.py", line 843, in urlopen
    retries = retries.increment(
              ^^^^^^^^^^^^^^^^^^
  File "/home/airflow/.local/lib/python3.12/site-packages/urllib3/util/retry.py", line 519, in increment
    raise MaxRetryError(_pool, url, reason) from reason  # type: ignore[arg-type]
    ^^^^^^^^^^^^^^^^^^^^^^^^^^^^^^^^^^^^^^^^^^^^^^^^^^^
urllib3.exceptions.MaxRetryError: HTTPConnectionPool(host='host.docker.internal', port=8000): Max retries exceeded with url: /api/simulators/ (Caused by NameResolutionError("<urllib3.connection.HTTPConnection object at 0x7ff5cc5b44d0>: Failed to resolve 'host.docker.internal' ([Errno -2] Name or service not known)"))

During handling of the above exception, another exception occurred:

Traceback (most recent call last):
  File "/home/airflow/.local/lib/python3.12/site-packages/airflow/models/dagbag.py", line 383, in parse
    loader.exec_module(new_module)
  File "<frozen importlib._bootstrap_external>", line 999, in exec_module
  File "<frozen importlib._bootstrap>", line 488, in _call_with_frames_removed
  File "/opt/airflow/dags/dynamic_dags.py", line 22, in <module>
    simulators = fetch_simulator_instances()
                 ^^^^^^^^^^^^^^^^^^^^^^^^^^^
  File "/opt/airflow/dags/dynamic_dags.py", line 10, in fetch_simulator_instances
    response = requests.get('http://host.docker.internal:8000/api/simulators/')
               ^^^^^^^^^^^^^^^^^^^^^^^^^^^^^^^^^^^^^^^^^^^^^^^^^^^^^^^^^^^^^^^^
  File "/home/airflow/.local/lib/python3.12/site-packages/requests/api.py", line 73, in get
    return request("get", url, params=params, **kwargs)
           ^^^^^^^^^^^^^^^^^^^^^^^^^^^^^^^^^^^^^^^^^^^^
  File "/home/airflow/.local/lib/python3.12/site-packages/requests/api.py", line 59, in request
    return session.request(method=method, url=url, **kwargs)
           ^^^^^^^^^^^^^^^^^^^^^^^^^^^^^^^^^^^^^^^^^^^^^^^^^
  File "/home/airflow/.local/lib/python3.12/site-packages/requests/sessions.py", line 589, in request
    resp = self.send(prep, **send_kwargs)
           ^^^^^^^^^^^^^^^^^^^^^^^^^^^^^^
  File "/home/airflow/.local/lib/python3.12/site-packages/requests/sessions.py", line 703, in send
    r = adapter.send(request, **kwargs)
        ^^^^^^^^^^^^^^^^^^^^^^^^^^^^^^^
  File "/home/airflow/.local/lib/python3.12/site-packages/requests/adapters.py", line 700, in send
    raise ConnectionError(e, request=request)
requests.exceptions.ConnectionError: HTTPConnectionPool(host='host.docker.internal', port=8000): Max retries exceeded with url: /api/simulators/ (Caused by NameResolutionError("<urllib3.connection.HTTPConnection object at 0x7ff5cc5b44d0>: Failed to resolve 'host.docker.internal' ([Errno -2] Name or service not known)"))
[2024-12-24T22:35:01.219+0000] {processor.py:927} WARNING - No viable dags retrieved from /opt/airflow/dags/dynamic_dags.py
[2024-12-24T22:35:01.239+0000] {processor.py:208} INFO - Processing /opt/airflow/dags/dynamic_dags.py took 8.184 seconds
[2024-12-24T22:35:31.404+0000] {processor.py:186} INFO - Started process (PID=475) to work on /opt/airflow/dags/dynamic_dags.py
[2024-12-24T22:35:31.406+0000] {processor.py:914} INFO - Processing file /opt/airflow/dags/dynamic_dags.py for tasks to queue
[2024-12-24T22:35:31.409+0000] {logging_mixin.py:190} INFO - [2024-12-24T22:35:31.409+0000] {dagbag.py:588} INFO - Filling up the DagBag from /opt/airflow/dags/dynamic_dags.py
[2024-12-24T22:35:41.499+0000] {logging_mixin.py:190} INFO - [2024-12-24T22:35:41.487+0000] {dagbag.py:387} ERROR - Failed to import: /opt/airflow/dags/dynamic_dags.py
Traceback (most recent call last):
  File "/home/airflow/.local/lib/python3.12/site-packages/urllib3/connection.py", line 199, in _new_conn
    sock = connection.create_connection(
           ^^^^^^^^^^^^^^^^^^^^^^^^^^^^^
  File "/home/airflow/.local/lib/python3.12/site-packages/urllib3/util/connection.py", line 60, in create_connection
    for res in socket.getaddrinfo(host, port, family, socket.SOCK_STREAM):
               ^^^^^^^^^^^^^^^^^^^^^^^^^^^^^^^^^^^^^^^^^^^^^^^^^^^^^^^^^^
  File "/usr/local/lib/python3.12/socket.py", line 976, in getaddrinfo
    for res in _socket.getaddrinfo(host, port, family, type, proto, flags):
               ^^^^^^^^^^^^^^^^^^^^^^^^^^^^^^^^^^^^^^^^^^^^^^^^^^^^^^^^^^^
socket.gaierror: [Errno -2] Name or service not known

The above exception was the direct cause of the following exception:

Traceback (most recent call last):
  File "/home/airflow/.local/lib/python3.12/site-packages/urllib3/connectionpool.py", line 789, in urlopen
    response = self._make_request(
               ^^^^^^^^^^^^^^^^^^^
  File "/home/airflow/.local/lib/python3.12/site-packages/urllib3/connectionpool.py", line 495, in _make_request
    conn.request(
  File "/home/airflow/.local/lib/python3.12/site-packages/urllib3/connection.py", line 441, in request
    self.endheaders()
  File "/usr/local/lib/python3.12/http/client.py", line 1331, in endheaders
    self._send_output(message_body, encode_chunked=encode_chunked)
  File "/usr/local/lib/python3.12/http/client.py", line 1091, in _send_output
    self.send(msg)
  File "/usr/local/lib/python3.12/http/client.py", line 1035, in send
    self.connect()
  File "/home/airflow/.local/lib/python3.12/site-packages/urllib3/connection.py", line 279, in connect
    self.sock = self._new_conn()
                ^^^^^^^^^^^^^^^^
  File "/home/airflow/.local/lib/python3.12/site-packages/urllib3/connection.py", line 206, in _new_conn
    raise NameResolutionError(self.host, self, e) from e
urllib3.exceptions.NameResolutionError: <urllib3.connection.HTTPConnection object at 0x7ff594b4cce0>: Failed to resolve 'host.docker.internal' ([Errno -2] Name or service not known)

The above exception was the direct cause of the following exception:

Traceback (most recent call last):
  File "/home/airflow/.local/lib/python3.12/site-packages/requests/adapters.py", line 667, in send
    resp = conn.urlopen(
           ^^^^^^^^^^^^^
  File "/home/airflow/.local/lib/python3.12/site-packages/urllib3/connectionpool.py", line 843, in urlopen
    retries = retries.increment(
              ^^^^^^^^^^^^^^^^^^
  File "/home/airflow/.local/lib/python3.12/site-packages/urllib3/util/retry.py", line 519, in increment
    raise MaxRetryError(_pool, url, reason) from reason  # type: ignore[arg-type]
    ^^^^^^^^^^^^^^^^^^^^^^^^^^^^^^^^^^^^^^^^^^^^^^^^^^^
urllib3.exceptions.MaxRetryError: HTTPConnectionPool(host='host.docker.internal', port=8000): Max retries exceeded with url: /api/simulators/ (Caused by NameResolutionError("<urllib3.connection.HTTPConnection object at 0x7ff594b4cce0>: Failed to resolve 'host.docker.internal' ([Errno -2] Name or service not known)"))

During handling of the above exception, another exception occurred:

Traceback (most recent call last):
  File "/home/airflow/.local/lib/python3.12/site-packages/airflow/models/dagbag.py", line 383, in parse
    loader.exec_module(new_module)
  File "<frozen importlib._bootstrap_external>", line 999, in exec_module
  File "<frozen importlib._bootstrap>", line 488, in _call_with_frames_removed
  File "/opt/airflow/dags/dynamic_dags.py", line 22, in <module>
    simulators = fetch_simulator_instances()
                 ^^^^^^^^^^^^^^^^^^^^^^^^^^^
  File "/opt/airflow/dags/dynamic_dags.py", line 10, in fetch_simulator_instances
    response = requests.get('http://host.docker.internal:8000/api/simulators/')
               ^^^^^^^^^^^^^^^^^^^^^^^^^^^^^^^^^^^^^^^^^^^^^^^^^^^^^^^^^^^^^^^^
  File "/home/airflow/.local/lib/python3.12/site-packages/requests/api.py", line 73, in get
    return request("get", url, params=params, **kwargs)
           ^^^^^^^^^^^^^^^^^^^^^^^^^^^^^^^^^^^^^^^^^^^^
  File "/home/airflow/.local/lib/python3.12/site-packages/requests/api.py", line 59, in request
    return session.request(method=method, url=url, **kwargs)
           ^^^^^^^^^^^^^^^^^^^^^^^^^^^^^^^^^^^^^^^^^^^^^^^^^
  File "/home/airflow/.local/lib/python3.12/site-packages/requests/sessions.py", line 589, in request
    resp = self.send(prep, **send_kwargs)
           ^^^^^^^^^^^^^^^^^^^^^^^^^^^^^^
  File "/home/airflow/.local/lib/python3.12/site-packages/requests/sessions.py", line 703, in send
    r = adapter.send(request, **kwargs)
        ^^^^^^^^^^^^^^^^^^^^^^^^^^^^^^^
  File "/home/airflow/.local/lib/python3.12/site-packages/requests/adapters.py", line 700, in send
    raise ConnectionError(e, request=request)
requests.exceptions.ConnectionError: HTTPConnectionPool(host='host.docker.internal', port=8000): Max retries exceeded with url: /api/simulators/ (Caused by NameResolutionError("<urllib3.connection.HTTPConnection object at 0x7ff594b4cce0>: Failed to resolve 'host.docker.internal' ([Errno -2] Name or service not known)"))
[2024-12-24T22:35:41.501+0000] {processor.py:927} WARNING - No viable dags retrieved from /opt/airflow/dags/dynamic_dags.py
[2024-12-24T22:35:41.545+0000] {processor.py:208} INFO - Processing /opt/airflow/dags/dynamic_dags.py took 8.170 seconds
[2024-12-24T22:36:11.732+0000] {processor.py:186} INFO - Started process (PID=577) to work on /opt/airflow/dags/dynamic_dags.py
[2024-12-24T22:36:11.734+0000] {processor.py:914} INFO - Processing file /opt/airflow/dags/dynamic_dags.py for tasks to queue
[2024-12-24T22:36:11.737+0000] {logging_mixin.py:190} INFO - [2024-12-24T22:36:11.737+0000] {dagbag.py:588} INFO - Filling up the DagBag from /opt/airflow/dags/dynamic_dags.py
[2024-12-24T22:36:19.852+0000] {logging_mixin.py:190} INFO - [2024-12-24T22:36:19.842+0000] {dagbag.py:387} ERROR - Failed to import: /opt/airflow/dags/dynamic_dags.py
Traceback (most recent call last):
  File "/home/airflow/.local/lib/python3.12/site-packages/urllib3/connection.py", line 199, in _new_conn
    sock = connection.create_connection(
           ^^^^^^^^^^^^^^^^^^^^^^^^^^^^^
  File "/home/airflow/.local/lib/python3.12/site-packages/urllib3/util/connection.py", line 60, in create_connection
    for res in socket.getaddrinfo(host, port, family, socket.SOCK_STREAM):
               ^^^^^^^^^^^^^^^^^^^^^^^^^^^^^^^^^^^^^^^^^^^^^^^^^^^^^^^^^^
  File "/usr/local/lib/python3.12/socket.py", line 976, in getaddrinfo
    for res in _socket.getaddrinfo(host, port, family, type, proto, flags):
               ^^^^^^^^^^^^^^^^^^^^^^^^^^^^^^^^^^^^^^^^^^^^^^^^^^^^^^^^^^^
socket.gaierror: [Errno -2] Name or service not known

The above exception was the direct cause of the following exception:

Traceback (most recent call last):
  File "/home/airflow/.local/lib/python3.12/site-packages/urllib3/connectionpool.py", line 789, in urlopen
    response = self._make_request(
               ^^^^^^^^^^^^^^^^^^^
  File "/home/airflow/.local/lib/python3.12/site-packages/urllib3/connectionpool.py", line 495, in _make_request
    conn.request(
  File "/home/airflow/.local/lib/python3.12/site-packages/urllib3/connection.py", line 441, in request
    self.endheaders()
  File "/usr/local/lib/python3.12/http/client.py", line 1331, in endheaders
    self._send_output(message_body, encode_chunked=encode_chunked)
  File "/usr/local/lib/python3.12/http/client.py", line 1091, in _send_output
    self.send(msg)
  File "/usr/local/lib/python3.12/http/client.py", line 1035, in send
    self.connect()
  File "/home/airflow/.local/lib/python3.12/site-packages/urllib3/connection.py", line 279, in connect
    self.sock = self._new_conn()
                ^^^^^^^^^^^^^^^^
  File "/home/airflow/.local/lib/python3.12/site-packages/urllib3/connection.py", line 206, in _new_conn
    raise NameResolutionError(self.host, self, e) from e
urllib3.exceptions.NameResolutionError: <urllib3.connection.HTTPConnection object at 0x7ff5cc5511c0>: Failed to resolve 'host.docker.internal' ([Errno -2] Name or service not known)

The above exception was the direct cause of the following exception:

Traceback (most recent call last):
  File "/home/airflow/.local/lib/python3.12/site-packages/requests/adapters.py", line 667, in send
    resp = conn.urlopen(
           ^^^^^^^^^^^^^
  File "/home/airflow/.local/lib/python3.12/site-packages/urllib3/connectionpool.py", line 843, in urlopen
    retries = retries.increment(
              ^^^^^^^^^^^^^^^^^^
  File "/home/airflow/.local/lib/python3.12/site-packages/urllib3/util/retry.py", line 519, in increment
    raise MaxRetryError(_pool, url, reason) from reason  # type: ignore[arg-type]
    ^^^^^^^^^^^^^^^^^^^^^^^^^^^^^^^^^^^^^^^^^^^^^^^^^^^
urllib3.exceptions.MaxRetryError: HTTPConnectionPool(host='host.docker.internal', port=8000): Max retries exceeded with url: /api/simulators/ (Caused by NameResolutionError("<urllib3.connection.HTTPConnection object at 0x7ff5cc5511c0>: Failed to resolve 'host.docker.internal' ([Errno -2] Name or service not known)"))

During handling of the above exception, another exception occurred:

Traceback (most recent call last):
  File "/home/airflow/.local/lib/python3.12/site-packages/airflow/models/dagbag.py", line 383, in parse
    loader.exec_module(new_module)
  File "<frozen importlib._bootstrap_external>", line 999, in exec_module
  File "<frozen importlib._bootstrap>", line 488, in _call_with_frames_removed
  File "/opt/airflow/dags/dynamic_dags.py", line 22, in <module>
    simulators = fetch_simulator_instances()
                 ^^^^^^^^^^^^^^^^^^^^^^^^^^^
  File "/opt/airflow/dags/dynamic_dags.py", line 10, in fetch_simulator_instances
    response = requests.get('http://host.docker.internal:8000/api/simulators/')
               ^^^^^^^^^^^^^^^^^^^^^^^^^^^^^^^^^^^^^^^^^^^^^^^^^^^^^^^^^^^^^^^^
  File "/home/airflow/.local/lib/python3.12/site-packages/requests/api.py", line 73, in get
    return request("get", url, params=params, **kwargs)
           ^^^^^^^^^^^^^^^^^^^^^^^^^^^^^^^^^^^^^^^^^^^^
  File "/home/airflow/.local/lib/python3.12/site-packages/requests/api.py", line 59, in request
    return session.request(method=method, url=url, **kwargs)
           ^^^^^^^^^^^^^^^^^^^^^^^^^^^^^^^^^^^^^^^^^^^^^^^^^
  File "/home/airflow/.local/lib/python3.12/site-packages/requests/sessions.py", line 589, in request
    resp = self.send(prep, **send_kwargs)
           ^^^^^^^^^^^^^^^^^^^^^^^^^^^^^^
  File "/home/airflow/.local/lib/python3.12/site-packages/requests/sessions.py", line 703, in send
    r = adapter.send(request, **kwargs)
        ^^^^^^^^^^^^^^^^^^^^^^^^^^^^^^^
  File "/home/airflow/.local/lib/python3.12/site-packages/requests/adapters.py", line 700, in send
    raise ConnectionError(e, request=request)
requests.exceptions.ConnectionError: HTTPConnectionPool(host='host.docker.internal', port=8000): Max retries exceeded with url: /api/simulators/ (Caused by NameResolutionError("<urllib3.connection.HTTPConnection object at 0x7ff5cc5511c0>: Failed to resolve 'host.docker.internal' ([Errno -2] Name or service not known)"))
[2024-12-24T22:36:19.854+0000] {processor.py:927} WARNING - No viable dags retrieved from /opt/airflow/dags/dynamic_dags.py
[2024-12-24T22:36:19.872+0000] {processor.py:208} INFO - Processing /opt/airflow/dags/dynamic_dags.py took 8.146 seconds
[2024-12-24T22:36:50.105+0000] {processor.py:186} INFO - Started process (PID=641) to work on /opt/airflow/dags/dynamic_dags.py
[2024-12-24T22:36:50.107+0000] {processor.py:914} INFO - Processing file /opt/airflow/dags/dynamic_dags.py for tasks to queue
[2024-12-24T22:36:50.111+0000] {logging_mixin.py:190} INFO - [2024-12-24T22:36:50.111+0000] {dagbag.py:588} INFO - Filling up the DagBag from /opt/airflow/dags/dynamic_dags.py
[2024-12-24T22:36:58.204+0000] {logging_mixin.py:190} INFO - [2024-12-24T22:36:58.193+0000] {dagbag.py:387} ERROR - Failed to import: /opt/airflow/dags/dynamic_dags.py
Traceback (most recent call last):
  File "/home/airflow/.local/lib/python3.12/site-packages/urllib3/connection.py", line 199, in _new_conn
    sock = connection.create_connection(
           ^^^^^^^^^^^^^^^^^^^^^^^^^^^^^
  File "/home/airflow/.local/lib/python3.12/site-packages/urllib3/util/connection.py", line 60, in create_connection
    for res in socket.getaddrinfo(host, port, family, socket.SOCK_STREAM):
               ^^^^^^^^^^^^^^^^^^^^^^^^^^^^^^^^^^^^^^^^^^^^^^^^^^^^^^^^^^
  File "/usr/local/lib/python3.12/socket.py", line 976, in getaddrinfo
    for res in _socket.getaddrinfo(host, port, family, type, proto, flags):
               ^^^^^^^^^^^^^^^^^^^^^^^^^^^^^^^^^^^^^^^^^^^^^^^^^^^^^^^^^^^
socket.gaierror: [Errno -2] Name or service not known

The above exception was the direct cause of the following exception:

Traceback (most recent call last):
  File "/home/airflow/.local/lib/python3.12/site-packages/urllib3/connectionpool.py", line 789, in urlopen
    response = self._make_request(
               ^^^^^^^^^^^^^^^^^^^
  File "/home/airflow/.local/lib/python3.12/site-packages/urllib3/connectionpool.py", line 495, in _make_request
    conn.request(
  File "/home/airflow/.local/lib/python3.12/site-packages/urllib3/connection.py", line 441, in request
    self.endheaders()
  File "/usr/local/lib/python3.12/http/client.py", line 1331, in endheaders
    self._send_output(message_body, encode_chunked=encode_chunked)
  File "/usr/local/lib/python3.12/http/client.py", line 1091, in _send_output
    self.send(msg)
  File "/usr/local/lib/python3.12/http/client.py", line 1035, in send
    self.connect()
  File "/home/airflow/.local/lib/python3.12/site-packages/urllib3/connection.py", line 279, in connect
    self.sock = self._new_conn()
                ^^^^^^^^^^^^^^^^
  File "/home/airflow/.local/lib/python3.12/site-packages/urllib3/connection.py", line 206, in _new_conn
    raise NameResolutionError(self.host, self, e) from e
urllib3.exceptions.NameResolutionError: <urllib3.connection.HTTPConnection object at 0x7ff594cac8c0>: Failed to resolve 'host.docker.internal' ([Errno -2] Name or service not known)

The above exception was the direct cause of the following exception:

Traceback (most recent call last):
  File "/home/airflow/.local/lib/python3.12/site-packages/requests/adapters.py", line 667, in send
    resp = conn.urlopen(
           ^^^^^^^^^^^^^
  File "/home/airflow/.local/lib/python3.12/site-packages/urllib3/connectionpool.py", line 843, in urlopen
    retries = retries.increment(
              ^^^^^^^^^^^^^^^^^^
  File "/home/airflow/.local/lib/python3.12/site-packages/urllib3/util/retry.py", line 519, in increment
    raise MaxRetryError(_pool, url, reason) from reason  # type: ignore[arg-type]
    ^^^^^^^^^^^^^^^^^^^^^^^^^^^^^^^^^^^^^^^^^^^^^^^^^^^
urllib3.exceptions.MaxRetryError: HTTPConnectionPool(host='host.docker.internal', port=8000): Max retries exceeded with url: /api/simulators/ (Caused by NameResolutionError("<urllib3.connection.HTTPConnection object at 0x7ff594cac8c0>: Failed to resolve 'host.docker.internal' ([Errno -2] Name or service not known)"))

During handling of the above exception, another exception occurred:

Traceback (most recent call last):
  File "/home/airflow/.local/lib/python3.12/site-packages/airflow/models/dagbag.py", line 383, in parse
    loader.exec_module(new_module)
  File "<frozen importlib._bootstrap_external>", line 999, in exec_module
  File "<frozen importlib._bootstrap>", line 488, in _call_with_frames_removed
  File "/opt/airflow/dags/dynamic_dags.py", line 22, in <module>
    simulators = fetch_simulator_instances()
                 ^^^^^^^^^^^^^^^^^^^^^^^^^^^
  File "/opt/airflow/dags/dynamic_dags.py", line 10, in fetch_simulator_instances
    response = requests.get('http://host.docker.internal:8000/api/simulators/')
               ^^^^^^^^^^^^^^^^^^^^^^^^^^^^^^^^^^^^^^^^^^^^^^^^^^^^^^^^^^^^^^^^
  File "/home/airflow/.local/lib/python3.12/site-packages/requests/api.py", line 73, in get
    return request("get", url, params=params, **kwargs)
           ^^^^^^^^^^^^^^^^^^^^^^^^^^^^^^^^^^^^^^^^^^^^
  File "/home/airflow/.local/lib/python3.12/site-packages/requests/api.py", line 59, in request
    return session.request(method=method, url=url, **kwargs)
           ^^^^^^^^^^^^^^^^^^^^^^^^^^^^^^^^^^^^^^^^^^^^^^^^^
  File "/home/airflow/.local/lib/python3.12/site-packages/requests/sessions.py", line 589, in request
    resp = self.send(prep, **send_kwargs)
           ^^^^^^^^^^^^^^^^^^^^^^^^^^^^^^
  File "/home/airflow/.local/lib/python3.12/site-packages/requests/sessions.py", line 703, in send
    r = adapter.send(request, **kwargs)
        ^^^^^^^^^^^^^^^^^^^^^^^^^^^^^^^
  File "/home/airflow/.local/lib/python3.12/site-packages/requests/adapters.py", line 700, in send
    raise ConnectionError(e, request=request)
requests.exceptions.ConnectionError: HTTPConnectionPool(host='host.docker.internal', port=8000): Max retries exceeded with url: /api/simulators/ (Caused by NameResolutionError("<urllib3.connection.HTTPConnection object at 0x7ff594cac8c0>: Failed to resolve 'host.docker.internal' ([Errno -2] Name or service not known)"))
[2024-12-24T22:36:58.205+0000] {processor.py:927} WARNING - No viable dags retrieved from /opt/airflow/dags/dynamic_dags.py
[2024-12-24T22:36:58.220+0000] {processor.py:208} INFO - Processing /opt/airflow/dags/dynamic_dags.py took 8.122 seconds
[2024-12-24T22:37:28.638+0000] {processor.py:186} INFO - Started process (PID=709) to work on /opt/airflow/dags/dynamic_dags.py
[2024-12-24T22:37:28.640+0000] {processor.py:914} INFO - Processing file /opt/airflow/dags/dynamic_dags.py for tasks to queue
[2024-12-24T22:37:28.642+0000] {logging_mixin.py:190} INFO - [2024-12-24T22:37:28.642+0000] {dagbag.py:588} INFO - Filling up the DagBag from /opt/airflow/dags/dynamic_dags.py
[2024-12-24T22:37:36.787+0000] {logging_mixin.py:190} INFO - [2024-12-24T22:37:36.772+0000] {dagbag.py:387} ERROR - Failed to import: /opt/airflow/dags/dynamic_dags.py
Traceback (most recent call last):
  File "/home/airflow/.local/lib/python3.12/site-packages/urllib3/connection.py", line 199, in _new_conn
    sock = connection.create_connection(
           ^^^^^^^^^^^^^^^^^^^^^^^^^^^^^
  File "/home/airflow/.local/lib/python3.12/site-packages/urllib3/util/connection.py", line 60, in create_connection
    for res in socket.getaddrinfo(host, port, family, socket.SOCK_STREAM):
               ^^^^^^^^^^^^^^^^^^^^^^^^^^^^^^^^^^^^^^^^^^^^^^^^^^^^^^^^^^
  File "/usr/local/lib/python3.12/socket.py", line 976, in getaddrinfo
    for res in _socket.getaddrinfo(host, port, family, type, proto, flags):
               ^^^^^^^^^^^^^^^^^^^^^^^^^^^^^^^^^^^^^^^^^^^^^^^^^^^^^^^^^^^
socket.gaierror: [Errno -2] Name or service not known

The above exception was the direct cause of the following exception:

Traceback (most recent call last):
  File "/home/airflow/.local/lib/python3.12/site-packages/urllib3/connectionpool.py", line 789, in urlopen
    response = self._make_request(
               ^^^^^^^^^^^^^^^^^^^
  File "/home/airflow/.local/lib/python3.12/site-packages/urllib3/connectionpool.py", line 495, in _make_request
    conn.request(
  File "/home/airflow/.local/lib/python3.12/site-packages/urllib3/connection.py", line 441, in request
    self.endheaders()
  File "/usr/local/lib/python3.12/http/client.py", line 1331, in endheaders
    self._send_output(message_body, encode_chunked=encode_chunked)
  File "/usr/local/lib/python3.12/http/client.py", line 1091, in _send_output
    self.send(msg)
  File "/usr/local/lib/python3.12/http/client.py", line 1035, in send
    self.connect()
  File "/home/airflow/.local/lib/python3.12/site-packages/urllib3/connection.py", line 279, in connect
    self.sock = self._new_conn()
                ^^^^^^^^^^^^^^^^
  File "/home/airflow/.local/lib/python3.12/site-packages/urllib3/connection.py", line 206, in _new_conn
    raise NameResolutionError(self.host, self, e) from e
urllib3.exceptions.NameResolutionError: <urllib3.connection.HTTPConnection object at 0x7ff5cc41d910>: Failed to resolve 'host.docker.internal' ([Errno -2] Name or service not known)

The above exception was the direct cause of the following exception:

Traceback (most recent call last):
  File "/home/airflow/.local/lib/python3.12/site-packages/requests/adapters.py", line 667, in send
    resp = conn.urlopen(
           ^^^^^^^^^^^^^
  File "/home/airflow/.local/lib/python3.12/site-packages/urllib3/connectionpool.py", line 843, in urlopen
    retries = retries.increment(
              ^^^^^^^^^^^^^^^^^^
  File "/home/airflow/.local/lib/python3.12/site-packages/urllib3/util/retry.py", line 519, in increment
    raise MaxRetryError(_pool, url, reason) from reason  # type: ignore[arg-type]
    ^^^^^^^^^^^^^^^^^^^^^^^^^^^^^^^^^^^^^^^^^^^^^^^^^^^
urllib3.exceptions.MaxRetryError: HTTPConnectionPool(host='host.docker.internal', port=8000): Max retries exceeded with url: /api/simulators/ (Caused by NameResolutionError("<urllib3.connection.HTTPConnection object at 0x7ff5cc41d910>: Failed to resolve 'host.docker.internal' ([Errno -2] Name or service not known)"))

During handling of the above exception, another exception occurred:

Traceback (most recent call last):
  File "/home/airflow/.local/lib/python3.12/site-packages/airflow/models/dagbag.py", line 383, in parse
    loader.exec_module(new_module)
  File "<frozen importlib._bootstrap_external>", line 999, in exec_module
  File "<frozen importlib._bootstrap>", line 488, in _call_with_frames_removed
  File "/opt/airflow/dags/dynamic_dags.py", line 22, in <module>
    simulators = fetch_simulator_instances()
                 ^^^^^^^^^^^^^^^^^^^^^^^^^^^
  File "/opt/airflow/dags/dynamic_dags.py", line 10, in fetch_simulator_instances
    response = requests.get('http://host.docker.internal:8000/api/simulators/')
               ^^^^^^^^^^^^^^^^^^^^^^^^^^^^^^^^^^^^^^^^^^^^^^^^^^^^^^^^^^^^^^^^
  File "/home/airflow/.local/lib/python3.12/site-packages/requests/api.py", line 73, in get
    return request("get", url, params=params, **kwargs)
           ^^^^^^^^^^^^^^^^^^^^^^^^^^^^^^^^^^^^^^^^^^^^
  File "/home/airflow/.local/lib/python3.12/site-packages/requests/api.py", line 59, in request
    return session.request(method=method, url=url, **kwargs)
           ^^^^^^^^^^^^^^^^^^^^^^^^^^^^^^^^^^^^^^^^^^^^^^^^^
  File "/home/airflow/.local/lib/python3.12/site-packages/requests/sessions.py", line 589, in request
    resp = self.send(prep, **send_kwargs)
           ^^^^^^^^^^^^^^^^^^^^^^^^^^^^^^
  File "/home/airflow/.local/lib/python3.12/site-packages/requests/sessions.py", line 703, in send
    r = adapter.send(request, **kwargs)
        ^^^^^^^^^^^^^^^^^^^^^^^^^^^^^^^
  File "/home/airflow/.local/lib/python3.12/site-packages/requests/adapters.py", line 700, in send
    raise ConnectionError(e, request=request)
requests.exceptions.ConnectionError: HTTPConnectionPool(host='host.docker.internal', port=8000): Max retries exceeded with url: /api/simulators/ (Caused by NameResolutionError("<urllib3.connection.HTTPConnection object at 0x7ff5cc41d910>: Failed to resolve 'host.docker.internal' ([Errno -2] Name or service not known)"))
[2024-12-24T22:37:36.789+0000] {processor.py:927} WARNING - No viable dags retrieved from /opt/airflow/dags/dynamic_dags.py
[2024-12-24T22:37:36.806+0000] {processor.py:208} INFO - Processing /opt/airflow/dags/dynamic_dags.py took 8.172 seconds
[2024-12-24T22:38:07.552+0000] {processor.py:186} INFO - Started process (PID=794) to work on /opt/airflow/dags/dynamic_dags.py
[2024-12-24T22:38:07.554+0000] {processor.py:914} INFO - Processing file /opt/airflow/dags/dynamic_dags.py for tasks to queue
[2024-12-24T22:38:07.557+0000] {logging_mixin.py:190} INFO - [2024-12-24T22:38:07.556+0000] {dagbag.py:588} INFO - Filling up the DagBag from /opt/airflow/dags/dynamic_dags.py
[2024-12-24T22:38:15.646+0000] {logging_mixin.py:190} INFO - [2024-12-24T22:38:15.637+0000] {dagbag.py:387} ERROR - Failed to import: /opt/airflow/dags/dynamic_dags.py
Traceback (most recent call last):
  File "/home/airflow/.local/lib/python3.12/site-packages/urllib3/connection.py", line 199, in _new_conn
    sock = connection.create_connection(
           ^^^^^^^^^^^^^^^^^^^^^^^^^^^^^
  File "/home/airflow/.local/lib/python3.12/site-packages/urllib3/util/connection.py", line 60, in create_connection
    for res in socket.getaddrinfo(host, port, family, socket.SOCK_STREAM):
               ^^^^^^^^^^^^^^^^^^^^^^^^^^^^^^^^^^^^^^^^^^^^^^^^^^^^^^^^^^
  File "/usr/local/lib/python3.12/socket.py", line 976, in getaddrinfo
    for res in _socket.getaddrinfo(host, port, family, type, proto, flags):
               ^^^^^^^^^^^^^^^^^^^^^^^^^^^^^^^^^^^^^^^^^^^^^^^^^^^^^^^^^^^
socket.gaierror: [Errno -2] Name or service not known

The above exception was the direct cause of the following exception:

Traceback (most recent call last):
  File "/home/airflow/.local/lib/python3.12/site-packages/urllib3/connectionpool.py", line 789, in urlopen
    response = self._make_request(
               ^^^^^^^^^^^^^^^^^^^
  File "/home/airflow/.local/lib/python3.12/site-packages/urllib3/connectionpool.py", line 495, in _make_request
    conn.request(
  File "/home/airflow/.local/lib/python3.12/site-packages/urllib3/connection.py", line 441, in request
    self.endheaders()
  File "/usr/local/lib/python3.12/http/client.py", line 1331, in endheaders
    self._send_output(message_body, encode_chunked=encode_chunked)
  File "/usr/local/lib/python3.12/http/client.py", line 1091, in _send_output
    self.send(msg)
  File "/usr/local/lib/python3.12/http/client.py", line 1035, in send
    self.connect()
  File "/home/airflow/.local/lib/python3.12/site-packages/urllib3/connection.py", line 279, in connect
    self.sock = self._new_conn()
                ^^^^^^^^^^^^^^^^
  File "/home/airflow/.local/lib/python3.12/site-packages/urllib3/connection.py", line 206, in _new_conn
    raise NameResolutionError(self.host, self, e) from e
urllib3.exceptions.NameResolutionError: <urllib3.connection.HTTPConnection object at 0x7ff5cc5b46b0>: Failed to resolve 'host.docker.internal' ([Errno -2] Name or service not known)

The above exception was the direct cause of the following exception:

Traceback (most recent call last):
  File "/home/airflow/.local/lib/python3.12/site-packages/requests/adapters.py", line 667, in send
    resp = conn.urlopen(
           ^^^^^^^^^^^^^
  File "/home/airflow/.local/lib/python3.12/site-packages/urllib3/connectionpool.py", line 843, in urlopen
    retries = retries.increment(
              ^^^^^^^^^^^^^^^^^^
  File "/home/airflow/.local/lib/python3.12/site-packages/urllib3/util/retry.py", line 519, in increment
    raise MaxRetryError(_pool, url, reason) from reason  # type: ignore[arg-type]
    ^^^^^^^^^^^^^^^^^^^^^^^^^^^^^^^^^^^^^^^^^^^^^^^^^^^
urllib3.exceptions.MaxRetryError: HTTPConnectionPool(host='host.docker.internal', port=8000): Max retries exceeded with url: /api/simulators/ (Caused by NameResolutionError("<urllib3.connection.HTTPConnection object at 0x7ff5cc5b46b0>: Failed to resolve 'host.docker.internal' ([Errno -2] Name or service not known)"))

During handling of the above exception, another exception occurred:

Traceback (most recent call last):
  File "/home/airflow/.local/lib/python3.12/site-packages/airflow/models/dagbag.py", line 383, in parse
    loader.exec_module(new_module)
  File "<frozen importlib._bootstrap_external>", line 999, in exec_module
  File "<frozen importlib._bootstrap>", line 488, in _call_with_frames_removed
  File "/opt/airflow/dags/dynamic_dags.py", line 22, in <module>
    simulators = fetch_simulator_instances()
                 ^^^^^^^^^^^^^^^^^^^^^^^^^^^
  File "/opt/airflow/dags/dynamic_dags.py", line 10, in fetch_simulator_instances
    response = requests.get('http://host.docker.internal:8000/api/simulators/')
               ^^^^^^^^^^^^^^^^^^^^^^^^^^^^^^^^^^^^^^^^^^^^^^^^^^^^^^^^^^^^^^^^
  File "/home/airflow/.local/lib/python3.12/site-packages/requests/api.py", line 73, in get
    return request("get", url, params=params, **kwargs)
           ^^^^^^^^^^^^^^^^^^^^^^^^^^^^^^^^^^^^^^^^^^^^
  File "/home/airflow/.local/lib/python3.12/site-packages/requests/api.py", line 59, in request
    return session.request(method=method, url=url, **kwargs)
           ^^^^^^^^^^^^^^^^^^^^^^^^^^^^^^^^^^^^^^^^^^^^^^^^^
  File "/home/airflow/.local/lib/python3.12/site-packages/requests/sessions.py", line 589, in request
    resp = self.send(prep, **send_kwargs)
           ^^^^^^^^^^^^^^^^^^^^^^^^^^^^^^
  File "/home/airflow/.local/lib/python3.12/site-packages/requests/sessions.py", line 703, in send
    r = adapter.send(request, **kwargs)
        ^^^^^^^^^^^^^^^^^^^^^^^^^^^^^^^
  File "/home/airflow/.local/lib/python3.12/site-packages/requests/adapters.py", line 700, in send
    raise ConnectionError(e, request=request)
requests.exceptions.ConnectionError: HTTPConnectionPool(host='host.docker.internal', port=8000): Max retries exceeded with url: /api/simulators/ (Caused by NameResolutionError("<urllib3.connection.HTTPConnection object at 0x7ff5cc5b46b0>: Failed to resolve 'host.docker.internal' ([Errno -2] Name or service not known)"))
[2024-12-24T22:38:15.648+0000] {processor.py:927} WARNING - No viable dags retrieved from /opt/airflow/dags/dynamic_dags.py
[2024-12-24T22:38:15.667+0000] {processor.py:208} INFO - Processing /opt/airflow/dags/dynamic_dags.py took 8.120 seconds
[2024-12-24T22:38:45.924+0000] {processor.py:186} INFO - Started process (PID=886) to work on /opt/airflow/dags/dynamic_dags.py
[2024-12-24T22:38:45.926+0000] {processor.py:914} INFO - Processing file /opt/airflow/dags/dynamic_dags.py for tasks to queue
[2024-12-24T22:38:45.929+0000] {logging_mixin.py:190} INFO - [2024-12-24T22:38:45.928+0000] {dagbag.py:588} INFO - Filling up the DagBag from /opt/airflow/dags/dynamic_dags.py
[2024-12-24T22:38:54.045+0000] {logging_mixin.py:190} INFO - [2024-12-24T22:38:54.030+0000] {dagbag.py:387} ERROR - Failed to import: /opt/airflow/dags/dynamic_dags.py
Traceback (most recent call last):
  File "/home/airflow/.local/lib/python3.12/site-packages/urllib3/connection.py", line 199, in _new_conn
    sock = connection.create_connection(
           ^^^^^^^^^^^^^^^^^^^^^^^^^^^^^
  File "/home/airflow/.local/lib/python3.12/site-packages/urllib3/util/connection.py", line 60, in create_connection
    for res in socket.getaddrinfo(host, port, family, socket.SOCK_STREAM):
               ^^^^^^^^^^^^^^^^^^^^^^^^^^^^^^^^^^^^^^^^^^^^^^^^^^^^^^^^^^
  File "/usr/local/lib/python3.12/socket.py", line 976, in getaddrinfo
    for res in _socket.getaddrinfo(host, port, family, type, proto, flags):
               ^^^^^^^^^^^^^^^^^^^^^^^^^^^^^^^^^^^^^^^^^^^^^^^^^^^^^^^^^^^
socket.gaierror: [Errno -2] Name or service not known

The above exception was the direct cause of the following exception:

Traceback (most recent call last):
  File "/home/airflow/.local/lib/python3.12/site-packages/urllib3/connectionpool.py", line 789, in urlopen
    response = self._make_request(
               ^^^^^^^^^^^^^^^^^^^
  File "/home/airflow/.local/lib/python3.12/site-packages/urllib3/connectionpool.py", line 495, in _make_request
    conn.request(
  File "/home/airflow/.local/lib/python3.12/site-packages/urllib3/connection.py", line 441, in request
    self.endheaders()
  File "/usr/local/lib/python3.12/http/client.py", line 1331, in endheaders
    self._send_output(message_body, encode_chunked=encode_chunked)
  File "/usr/local/lib/python3.12/http/client.py", line 1091, in _send_output
    self.send(msg)
  File "/usr/local/lib/python3.12/http/client.py", line 1035, in send
    self.connect()
  File "/home/airflow/.local/lib/python3.12/site-packages/urllib3/connection.py", line 279, in connect
    self.sock = self._new_conn()
                ^^^^^^^^^^^^^^^^
  File "/home/airflow/.local/lib/python3.12/site-packages/urllib3/connection.py", line 206, in _new_conn
    raise NameResolutionError(self.host, self, e) from e
urllib3.exceptions.NameResolutionError: <urllib3.connection.HTTPConnection object at 0x7ff5cc5530b0>: Failed to resolve 'host.docker.internal' ([Errno -2] Name or service not known)

The above exception was the direct cause of the following exception:

Traceback (most recent call last):
  File "/home/airflow/.local/lib/python3.12/site-packages/requests/adapters.py", line 667, in send
    resp = conn.urlopen(
           ^^^^^^^^^^^^^
  File "/home/airflow/.local/lib/python3.12/site-packages/urllib3/connectionpool.py", line 843, in urlopen
    retries = retries.increment(
              ^^^^^^^^^^^^^^^^^^
  File "/home/airflow/.local/lib/python3.12/site-packages/urllib3/util/retry.py", line 519, in increment
    raise MaxRetryError(_pool, url, reason) from reason  # type: ignore[arg-type]
    ^^^^^^^^^^^^^^^^^^^^^^^^^^^^^^^^^^^^^^^^^^^^^^^^^^^
urllib3.exceptions.MaxRetryError: HTTPConnectionPool(host='host.docker.internal', port=8000): Max retries exceeded with url: /api/simulators/ (Caused by NameResolutionError("<urllib3.connection.HTTPConnection object at 0x7ff5cc5530b0>: Failed to resolve 'host.docker.internal' ([Errno -2] Name or service not known)"))

During handling of the above exception, another exception occurred:

Traceback (most recent call last):
  File "/home/airflow/.local/lib/python3.12/site-packages/airflow/models/dagbag.py", line 383, in parse
    loader.exec_module(new_module)
  File "<frozen importlib._bootstrap_external>", line 999, in exec_module
  File "<frozen importlib._bootstrap>", line 488, in _call_with_frames_removed
  File "/opt/airflow/dags/dynamic_dags.py", line 22, in <module>
    simulators = fetch_simulator_instances()
                 ^^^^^^^^^^^^^^^^^^^^^^^^^^^
  File "/opt/airflow/dags/dynamic_dags.py", line 10, in fetch_simulator_instances
    response = requests.get('http://host.docker.internal:8000/api/simulators/')
               ^^^^^^^^^^^^^^^^^^^^^^^^^^^^^^^^^^^^^^^^^^^^^^^^^^^^^^^^^^^^^^^^
  File "/home/airflow/.local/lib/python3.12/site-packages/requests/api.py", line 73, in get
    return request("get", url, params=params, **kwargs)
           ^^^^^^^^^^^^^^^^^^^^^^^^^^^^^^^^^^^^^^^^^^^^
  File "/home/airflow/.local/lib/python3.12/site-packages/requests/api.py", line 59, in request
    return session.request(method=method, url=url, **kwargs)
           ^^^^^^^^^^^^^^^^^^^^^^^^^^^^^^^^^^^^^^^^^^^^^^^^^
  File "/home/airflow/.local/lib/python3.12/site-packages/requests/sessions.py", line 589, in request
    resp = self.send(prep, **send_kwargs)
           ^^^^^^^^^^^^^^^^^^^^^^^^^^^^^^
  File "/home/airflow/.local/lib/python3.12/site-packages/requests/sessions.py", line 703, in send
    r = adapter.send(request, **kwargs)
        ^^^^^^^^^^^^^^^^^^^^^^^^^^^^^^^
  File "/home/airflow/.local/lib/python3.12/site-packages/requests/adapters.py", line 700, in send
    raise ConnectionError(e, request=request)
requests.exceptions.ConnectionError: HTTPConnectionPool(host='host.docker.internal', port=8000): Max retries exceeded with url: /api/simulators/ (Caused by NameResolutionError("<urllib3.connection.HTTPConnection object at 0x7ff5cc5530b0>: Failed to resolve 'host.docker.internal' ([Errno -2] Name or service not known)"))
[2024-12-24T22:38:54.047+0000] {processor.py:927} WARNING - No viable dags retrieved from /opt/airflow/dags/dynamic_dags.py
[2024-12-24T22:38:54.068+0000] {processor.py:208} INFO - Processing /opt/airflow/dags/dynamic_dags.py took 8.149 seconds
[2024-12-24T22:44:27.951+0000] {processor.py:186} INFO - Started process (PID=65) to work on /opt/airflow/dags/dynamic_dags.py
[2024-12-24T22:44:27.967+0000] {processor.py:914} INFO - Processing file /opt/airflow/dags/dynamic_dags.py for tasks to queue
[2024-12-24T22:44:27.972+0000] {logging_mixin.py:190} INFO - [2024-12-24T22:44:27.971+0000] {dagbag.py:588} INFO - Filling up the DagBag from /opt/airflow/dags/dynamic_dags.py
[2024-12-24T22:44:28.072+0000] {logging_mixin.py:190} INFO - Error fetching simulator instances: 404 Client Error: Not Found for url: http://172.17.0.1:8000/api/simulators/
[2024-12-24T22:44:28.074+0000] {processor.py:927} WARNING - No viable dags retrieved from /opt/airflow/dags/dynamic_dags.py
[2024-12-24T22:44:28.098+0000] {processor.py:208} INFO - Processing /opt/airflow/dags/dynamic_dags.py took 0.165 seconds
[2024-12-24T22:44:58.645+0000] {processor.py:186} INFO - Started process (PID=130) to work on /opt/airflow/dags/dynamic_dags.py
[2024-12-24T22:44:58.650+0000] {processor.py:914} INFO - Processing file /opt/airflow/dags/dynamic_dags.py for tasks to queue
[2024-12-24T22:44:58.654+0000] {logging_mixin.py:190} INFO - [2024-12-24T22:44:58.653+0000] {dagbag.py:588} INFO - Filling up the DagBag from /opt/airflow/dags/dynamic_dags.py
[2024-12-24T22:44:58.816+0000] {logging_mixin.py:190} INFO - Error fetching simulator instances: 404 Client Error: Not Found for url: http://172.17.0.1:8000/api/simulators/
[2024-12-24T22:44:58.827+0000] {processor.py:927} WARNING - No viable dags retrieved from /opt/airflow/dags/dynamic_dags.py
[2024-12-24T22:44:58.843+0000] {processor.py:208} INFO - Processing /opt/airflow/dags/dynamic_dags.py took 0.205 seconds
[2024-12-24T22:45:29.463+0000] {processor.py:186} INFO - Started process (PID=194) to work on /opt/airflow/dags/dynamic_dags.py
[2024-12-24T22:45:29.466+0000] {processor.py:914} INFO - Processing file /opt/airflow/dags/dynamic_dags.py for tasks to queue
[2024-12-24T22:45:29.471+0000] {logging_mixin.py:190} INFO - [2024-12-24T22:45:29.470+0000] {dagbag.py:588} INFO - Filling up the DagBag from /opt/airflow/dags/dynamic_dags.py
[2024-12-24T22:45:29.538+0000] {logging_mixin.py:190} INFO - Error fetching simulator instances: 404 Client Error: Not Found for url: http://172.17.0.1:8000/api/simulators/
[2024-12-24T22:45:29.539+0000] {processor.py:927} WARNING - No viable dags retrieved from /opt/airflow/dags/dynamic_dags.py
[2024-12-24T22:45:29.556+0000] {processor.py:208} INFO - Processing /opt/airflow/dags/dynamic_dags.py took 0.100 seconds
[2024-12-24T22:46:00.596+0000] {processor.py:186} INFO - Started process (PID=258) to work on /opt/airflow/dags/dynamic_dags.py
[2024-12-24T22:46:00.600+0000] {processor.py:914} INFO - Processing file /opt/airflow/dags/dynamic_dags.py for tasks to queue
[2024-12-24T22:46:00.607+0000] {logging_mixin.py:190} INFO - [2024-12-24T22:46:00.606+0000] {dagbag.py:588} INFO - Filling up the DagBag from /opt/airflow/dags/dynamic_dags.py
[2024-12-24T22:46:00.862+0000] {logging_mixin.py:190} INFO - Error fetching simulator instances: 404 Client Error: Not Found for url: http://172.17.0.1:8000/api/simulators/
[2024-12-24T22:46:00.865+0000] {processor.py:927} WARNING - No viable dags retrieved from /opt/airflow/dags/dynamic_dags.py
[2024-12-24T22:46:00.883+0000] {processor.py:208} INFO - Processing /opt/airflow/dags/dynamic_dags.py took 0.295 seconds
[2024-12-24T22:46:31.688+0000] {processor.py:186} INFO - Started process (PID=322) to work on /opt/airflow/dags/dynamic_dags.py
[2024-12-24T22:46:31.707+0000] {processor.py:914} INFO - Processing file /opt/airflow/dags/dynamic_dags.py for tasks to queue
[2024-12-24T22:46:31.714+0000] {logging_mixin.py:190} INFO - [2024-12-24T22:46:31.713+0000] {dagbag.py:588} INFO - Filling up the DagBag from /opt/airflow/dags/dynamic_dags.py
[2024-12-24T22:46:31.798+0000] {logging_mixin.py:190} INFO - Error fetching simulator instances: 404 Client Error: Not Found for url: http://172.17.0.1:8000/api/simulators/
[2024-12-24T22:46:31.801+0000] {processor.py:927} WARNING - No viable dags retrieved from /opt/airflow/dags/dynamic_dags.py
[2024-12-24T22:46:31.821+0000] {processor.py:208} INFO - Processing /opt/airflow/dags/dynamic_dags.py took 0.141 seconds
[2024-12-24T22:47:02.026+0000] {processor.py:186} INFO - Started process (PID=386) to work on /opt/airflow/dags/dynamic_dags.py
[2024-12-24T22:47:02.029+0000] {processor.py:914} INFO - Processing file /opt/airflow/dags/dynamic_dags.py for tasks to queue
[2024-12-24T22:47:02.034+0000] {logging_mixin.py:190} INFO - [2024-12-24T22:47:02.033+0000] {dagbag.py:588} INFO - Filling up the DagBag from /opt/airflow/dags/dynamic_dags.py
[2024-12-24T22:47:02.088+0000] {logging_mixin.py:190} INFO - Error fetching simulator instances: 404 Client Error: Not Found for url: http://172.17.0.1:8000/api/simulators/
[2024-12-24T22:47:02.089+0000] {processor.py:927} WARNING - No viable dags retrieved from /opt/airflow/dags/dynamic_dags.py
[2024-12-24T22:47:02.105+0000] {processor.py:208} INFO - Processing /opt/airflow/dags/dynamic_dags.py took 0.088 seconds
[2024-12-24T22:47:32.532+0000] {processor.py:186} INFO - Started process (PID=450) to work on /opt/airflow/dags/dynamic_dags.py
[2024-12-24T22:47:32.534+0000] {processor.py:914} INFO - Processing file /opt/airflow/dags/dynamic_dags.py for tasks to queue
[2024-12-24T22:47:32.536+0000] {logging_mixin.py:190} INFO - [2024-12-24T22:47:32.536+0000] {dagbag.py:588} INFO - Filling up the DagBag from /opt/airflow/dags/dynamic_dags.py
[2024-12-24T22:47:32.605+0000] {logging_mixin.py:190} INFO - Error fetching simulator instances: 404 Client Error: Not Found for url: http://172.17.0.1:8000/api/simulators/
[2024-12-24T22:47:32.607+0000] {processor.py:927} WARNING - No viable dags retrieved from /opt/airflow/dags/dynamic_dags.py
[2024-12-24T22:47:32.631+0000] {processor.py:208} INFO - Processing /opt/airflow/dags/dynamic_dags.py took 0.104 seconds
